[2024-12-04 11:53:22,028] {processor.py:153} INFO - Started process (PID=7283) to work on /home/airflow/dags/Lead_scoring_inference_pipeline/lead_scoring_inference_pipeline.py
[2024-12-04 11:53:22,029] {processor.py:641} INFO - Processing file /home/airflow/dags/Lead_scoring_inference_pipeline/lead_scoring_inference_pipeline.py for tasks to queue
[2024-12-04 11:53:22,029] {logging_mixin.py:115} INFO - [2024-12-04 11:53:22,029] {dagbag.py:508} INFO - Filling up the DagBag from /home/airflow/dags/Lead_scoring_inference_pipeline/lead_scoring_inference_pipeline.py
[2024-12-04 11:53:22,769] {logging_mixin.py:115} INFO - [2024-12-04 11:53:22,769] {utils.py:145} INFO - Note: NumExpr detected 64 cores but "NUMEXPR_MAX_THREADS" not set, so enforcing safe limit of 8.
[2024-12-04 11:53:22,769] {logging_mixin.py:115} INFO - [2024-12-04 11:53:22,769] {utils.py:157} INFO - NumExpr defaulting to 8 threads.
[2024-12-04 11:53:22,944] {processor.py:651} INFO - DAG(s) dict_keys(['Lead_scoring_inference_pipeline']) retrieved from /home/airflow/dags/Lead_scoring_inference_pipeline/lead_scoring_inference_pipeline.py
[2024-12-04 11:53:23,026] {logging_mixin.py:115} INFO - [2024-12-04 11:53:23,026] {manager.py:508} INFO - Created Permission View: can edit on DAG:Lead_scoring_inference_pipeline
[2024-12-04 11:53:23,042] {logging_mixin.py:115} INFO - [2024-12-04 11:53:23,042] {manager.py:508} INFO - Created Permission View: can delete on DAG:Lead_scoring_inference_pipeline
[2024-12-04 11:53:23,056] {logging_mixin.py:115} INFO - [2024-12-04 11:53:23,055] {manager.py:508} INFO - Created Permission View: can read on DAG:Lead_scoring_inference_pipeline
[2024-12-04 11:53:23,056] {logging_mixin.py:115} INFO - [2024-12-04 11:53:23,056] {dag.py:2420} INFO - Sync 1 DAGs
[2024-12-04 11:53:23,061] {logging_mixin.py:115} INFO - [2024-12-04 11:53:23,061] {dag.py:2439} INFO - Creating ORM DAG for Lead_scoring_inference_pipeline
[2024-12-04 11:53:23,069] {logging_mixin.py:115} INFO - [2024-12-04 11:53:23,069] {dag.py:2968} INFO - Setting next_dagrun for Lead_scoring_inference_pipeline to 2024-12-04T10:00:00+00:00, run_after=2024-12-04T11:00:00+00:00
[2024-12-04 11:53:23,091] {processor.py:161} INFO - Processing /home/airflow/dags/Lead_scoring_inference_pipeline/lead_scoring_inference_pipeline.py took 1.066 seconds
[2024-12-04 11:53:53,374] {processor.py:153} INFO - Started process (PID=7345) to work on /home/airflow/dags/Lead_scoring_inference_pipeline/lead_scoring_inference_pipeline.py
[2024-12-04 11:53:53,382] {processor.py:641} INFO - Processing file /home/airflow/dags/Lead_scoring_inference_pipeline/lead_scoring_inference_pipeline.py for tasks to queue
[2024-12-04 11:53:53,382] {logging_mixin.py:115} INFO - [2024-12-04 11:53:53,382] {dagbag.py:508} INFO - Filling up the DagBag from /home/airflow/dags/Lead_scoring_inference_pipeline/lead_scoring_inference_pipeline.py
[2024-12-04 11:53:54,131] {logging_mixin.py:115} INFO - [2024-12-04 11:53:54,130] {utils.py:145} INFO - Note: NumExpr detected 64 cores but "NUMEXPR_MAX_THREADS" not set, so enforcing safe limit of 8.
[2024-12-04 11:53:54,131] {logging_mixin.py:115} INFO - [2024-12-04 11:53:54,131] {utils.py:157} INFO - NumExpr defaulting to 8 threads.
[2024-12-04 11:53:54,305] {processor.py:651} INFO - DAG(s) dict_keys(['Lead_scoring_inference_pipeline']) retrieved from /home/airflow/dags/Lead_scoring_inference_pipeline/lead_scoring_inference_pipeline.py
[2024-12-04 11:53:54,317] {logging_mixin.py:115} INFO - [2024-12-04 11:53:54,317] {dag.py:2420} INFO - Sync 1 DAGs
[2024-12-04 11:53:54,330] {logging_mixin.py:115} INFO - [2024-12-04 11:53:54,330] {dag.py:2968} INFO - Setting next_dagrun for Lead_scoring_inference_pipeline to 2024-12-04T10:00:00+00:00, run_after=2024-12-04T11:00:00+00:00
[2024-12-04 11:53:54,351] {processor.py:161} INFO - Processing /home/airflow/dags/Lead_scoring_inference_pipeline/lead_scoring_inference_pipeline.py took 0.981 seconds
[2024-12-04 11:54:35,856] {processor.py:153} INFO - Started process (PID=7413) to work on /home/airflow/dags/Lead_scoring_inference_pipeline/lead_scoring_inference_pipeline.py
[2024-12-04 11:54:35,858] {processor.py:641} INFO - Processing file /home/airflow/dags/Lead_scoring_inference_pipeline/lead_scoring_inference_pipeline.py for tasks to queue
[2024-12-04 11:54:35,859] {logging_mixin.py:115} INFO - [2024-12-04 11:54:35,859] {dagbag.py:508} INFO - Filling up the DagBag from /home/airflow/dags/Lead_scoring_inference_pipeline/lead_scoring_inference_pipeline.py
[2024-12-04 11:54:35,866] {logging_mixin.py:115} INFO - [2024-12-04 11:54:35,866] {dagbag.py:321} ERROR - Failed to import: /home/airflow/dags/Lead_scoring_inference_pipeline/lead_scoring_inference_pipeline.py
Traceback (most recent call last):
  File "/opt/conda/lib/python3.8/site-packages/airflow/models/dagbag.py", line 318, in parse
    loader.exec_module(new_module)
  File "<frozen importlib._bootstrap_external>", line 843, in exec_module
  File "<frozen importlib._bootstrap>", line 219, in _call_with_frames_removed
  File "/home/airflow/dags/Lead_scoring_inference_pipeline/lead_scoring_inference_pipeline.py", line 36, in <module>
    utils = module_from_file("utils", "/airflow/dags/Lead_scoring_inference_pipeline/utils.py")
  File "/home/airflow/dags/Lead_scoring_inference_pipeline/lead_scoring_inference_pipeline.py", line 33, in module_from_file
    spec.loader.exec_module(module)
  File "<frozen importlib._bootstrap_external>", line 839, in exec_module
  File "<frozen importlib._bootstrap_external>", line 975, in get_code
  File "<frozen importlib._bootstrap_external>", line 1032, in get_data
FileNotFoundError: [Errno 2] No such file or directory: '/airflow/dags/Lead_scoring_inference_pipeline/utils.py'
[2024-12-04 11:54:35,867] {processor.py:653} WARNING - No viable dags retrieved from /home/airflow/dags/Lead_scoring_inference_pipeline/lead_scoring_inference_pipeline.py
[2024-12-04 11:54:35,893] {processor.py:161} INFO - Processing /home/airflow/dags/Lead_scoring_inference_pipeline/lead_scoring_inference_pipeline.py took 0.039 seconds
[2024-12-04 11:55:10,306] {processor.py:153} INFO - Started process (PID=7461) to work on /home/airflow/dags/Lead_scoring_inference_pipeline/lead_scoring_inference_pipeline.py
[2024-12-04 11:55:10,306] {processor.py:641} INFO - Processing file /home/airflow/dags/Lead_scoring_inference_pipeline/lead_scoring_inference_pipeline.py for tasks to queue
[2024-12-04 11:55:10,307] {logging_mixin.py:115} INFO - [2024-12-04 11:55:10,307] {dagbag.py:508} INFO - Filling up the DagBag from /home/airflow/dags/Lead_scoring_inference_pipeline/lead_scoring_inference_pipeline.py
[2024-12-04 11:55:10,315] {logging_mixin.py:115} INFO - [2024-12-04 11:55:10,314] {dagbag.py:321} ERROR - Failed to import: /home/airflow/dags/Lead_scoring_inference_pipeline/lead_scoring_inference_pipeline.py
Traceback (most recent call last):
  File "/opt/conda/lib/python3.8/site-packages/airflow/models/dagbag.py", line 318, in parse
    loader.exec_module(new_module)
  File "<frozen importlib._bootstrap_external>", line 843, in exec_module
  File "<frozen importlib._bootstrap>", line 219, in _call_with_frames_removed
  File "/home/airflow/dags/Lead_scoring_inference_pipeline/lead_scoring_inference_pipeline.py", line 36, in <module>
    utils = module_from_file("utils", "/airflow/dags/Lead_scoring_inference_pipeline/utils.py")
  File "/home/airflow/dags/Lead_scoring_inference_pipeline/lead_scoring_inference_pipeline.py", line 33, in module_from_file
    spec.loader.exec_module(module)
  File "<frozen importlib._bootstrap_external>", line 839, in exec_module
  File "<frozen importlib._bootstrap_external>", line 975, in get_code
  File "<frozen importlib._bootstrap_external>", line 1032, in get_data
FileNotFoundError: [Errno 2] No such file or directory: '/airflow/dags/Lead_scoring_inference_pipeline/utils.py'
[2024-12-04 11:55:10,315] {processor.py:653} WARNING - No viable dags retrieved from /home/airflow/dags/Lead_scoring_inference_pipeline/lead_scoring_inference_pipeline.py
[2024-12-04 11:55:10,340] {processor.py:161} INFO - Processing /home/airflow/dags/Lead_scoring_inference_pipeline/lead_scoring_inference_pipeline.py took 0.038 seconds
[2024-12-04 11:55:51,616] {processor.py:153} INFO - Started process (PID=7514) to work on /home/airflow/dags/Lead_scoring_inference_pipeline/lead_scoring_inference_pipeline.py
[2024-12-04 11:55:51,618] {processor.py:641} INFO - Processing file /home/airflow/dags/Lead_scoring_inference_pipeline/lead_scoring_inference_pipeline.py for tasks to queue
[2024-12-04 11:55:51,619] {logging_mixin.py:115} INFO - [2024-12-04 11:55:51,618] {dagbag.py:508} INFO - Filling up the DagBag from /home/airflow/dags/Lead_scoring_inference_pipeline/lead_scoring_inference_pipeline.py
[2024-12-04 11:55:51,627] {logging_mixin.py:115} INFO - [2024-12-04 11:55:51,626] {dagbag.py:321} ERROR - Failed to import: /home/airflow/dags/Lead_scoring_inference_pipeline/lead_scoring_inference_pipeline.py
Traceback (most recent call last):
  File "/opt/conda/lib/python3.8/site-packages/airflow/models/dagbag.py", line 318, in parse
    loader.exec_module(new_module)
  File "<frozen importlib._bootstrap_external>", line 843, in exec_module
  File "<frozen importlib._bootstrap>", line 219, in _call_with_frames_removed
  File "/home/airflow/dags/Lead_scoring_inference_pipeline/lead_scoring_inference_pipeline.py", line 36, in <module>
    utils = module_from_file("utils", "/airflow/dags/Lead_scoring_inference_pipeline/utils.py")
  File "/home/airflow/dags/Lead_scoring_inference_pipeline/lead_scoring_inference_pipeline.py", line 33, in module_from_file
    spec.loader.exec_module(module)
  File "<frozen importlib._bootstrap_external>", line 839, in exec_module
  File "<frozen importlib._bootstrap_external>", line 975, in get_code
  File "<frozen importlib._bootstrap_external>", line 1032, in get_data
FileNotFoundError: [Errno 2] No such file or directory: '/airflow/dags/Lead_scoring_inference_pipeline/utils.py'
[2024-12-04 11:55:51,627] {processor.py:653} WARNING - No viable dags retrieved from /home/airflow/dags/Lead_scoring_inference_pipeline/lead_scoring_inference_pipeline.py
[2024-12-04 11:55:51,654] {processor.py:161} INFO - Processing /home/airflow/dags/Lead_scoring_inference_pipeline/lead_scoring_inference_pipeline.py took 0.041 seconds
[2024-12-04 11:56:32,060] {processor.py:153} INFO - Started process (PID=7568) to work on /home/airflow/dags/Lead_scoring_inference_pipeline/lead_scoring_inference_pipeline.py
[2024-12-04 11:56:32,062] {processor.py:641} INFO - Processing file /home/airflow/dags/Lead_scoring_inference_pipeline/lead_scoring_inference_pipeline.py for tasks to queue
[2024-12-04 11:56:32,063] {logging_mixin.py:115} INFO - [2024-12-04 11:56:32,063] {dagbag.py:508} INFO - Filling up the DagBag from /home/airflow/dags/Lead_scoring_inference_pipeline/lead_scoring_inference_pipeline.py
[2024-12-04 11:56:32,071] {logging_mixin.py:115} INFO - [2024-12-04 11:56:32,070] {dagbag.py:321} ERROR - Failed to import: /home/airflow/dags/Lead_scoring_inference_pipeline/lead_scoring_inference_pipeline.py
Traceback (most recent call last):
  File "/opt/conda/lib/python3.8/site-packages/airflow/models/dagbag.py", line 318, in parse
    loader.exec_module(new_module)
  File "<frozen importlib._bootstrap_external>", line 843, in exec_module
  File "<frozen importlib._bootstrap>", line 219, in _call_with_frames_removed
  File "/home/airflow/dags/Lead_scoring_inference_pipeline/lead_scoring_inference_pipeline.py", line 36, in <module>
    utils = module_from_file("utils", "/airflow/dags/Lead_scoring_inference_pipeline/utils.py")
  File "/home/airflow/dags/Lead_scoring_inference_pipeline/lead_scoring_inference_pipeline.py", line 33, in module_from_file
    spec.loader.exec_module(module)
  File "<frozen importlib._bootstrap_external>", line 839, in exec_module
  File "<frozen importlib._bootstrap_external>", line 975, in get_code
  File "<frozen importlib._bootstrap_external>", line 1032, in get_data
FileNotFoundError: [Errno 2] No such file or directory: '/airflow/dags/Lead_scoring_inference_pipeline/utils.py'
[2024-12-04 11:56:32,071] {processor.py:653} WARNING - No viable dags retrieved from /home/airflow/dags/Lead_scoring_inference_pipeline/lead_scoring_inference_pipeline.py
[2024-12-04 11:56:32,096] {processor.py:161} INFO - Processing /home/airflow/dags/Lead_scoring_inference_pipeline/lead_scoring_inference_pipeline.py took 0.039 seconds
[2024-12-04 11:57:07,460] {processor.py:153} INFO - Started process (PID=7621) to work on /home/airflow/dags/Lead_scoring_inference_pipeline/lead_scoring_inference_pipeline.py
[2024-12-04 11:57:07,462] {processor.py:641} INFO - Processing file /home/airflow/dags/Lead_scoring_inference_pipeline/lead_scoring_inference_pipeline.py for tasks to queue
[2024-12-04 11:57:07,463] {logging_mixin.py:115} INFO - [2024-12-04 11:57:07,463] {dagbag.py:508} INFO - Filling up the DagBag from /home/airflow/dags/Lead_scoring_inference_pipeline/lead_scoring_inference_pipeline.py
[2024-12-04 11:57:07,471] {logging_mixin.py:115} INFO - [2024-12-04 11:57:07,471] {dagbag.py:321} ERROR - Failed to import: /home/airflow/dags/Lead_scoring_inference_pipeline/lead_scoring_inference_pipeline.py
Traceback (most recent call last):
  File "/opt/conda/lib/python3.8/site-packages/airflow/models/dagbag.py", line 318, in parse
    loader.exec_module(new_module)
  File "<frozen importlib._bootstrap_external>", line 843, in exec_module
  File "<frozen importlib._bootstrap>", line 219, in _call_with_frames_removed
  File "/home/airflow/dags/Lead_scoring_inference_pipeline/lead_scoring_inference_pipeline.py", line 36, in <module>
    utils = module_from_file("utils", "/airflow/dags/Lead_scoring_inference_pipeline/utils.py")
  File "/home/airflow/dags/Lead_scoring_inference_pipeline/lead_scoring_inference_pipeline.py", line 33, in module_from_file
    spec.loader.exec_module(module)
  File "<frozen importlib._bootstrap_external>", line 839, in exec_module
  File "<frozen importlib._bootstrap_external>", line 975, in get_code
  File "<frozen importlib._bootstrap_external>", line 1032, in get_data
FileNotFoundError: [Errno 2] No such file or directory: '/airflow/dags/Lead_scoring_inference_pipeline/utils.py'
[2024-12-04 11:57:07,472] {processor.py:653} WARNING - No viable dags retrieved from /home/airflow/dags/Lead_scoring_inference_pipeline/lead_scoring_inference_pipeline.py
[2024-12-04 11:57:07,495] {processor.py:161} INFO - Processing /home/airflow/dags/Lead_scoring_inference_pipeline/lead_scoring_inference_pipeline.py took 0.038 seconds
[2024-12-04 11:57:18,840] {processor.py:153} INFO - Started process (PID=7632) to work on /home/airflow/dags/Lead_scoring_inference_pipeline/lead_scoring_inference_pipeline.py
[2024-12-04 11:57:18,841] {processor.py:641} INFO - Processing file /home/airflow/dags/Lead_scoring_inference_pipeline/lead_scoring_inference_pipeline.py for tasks to queue
[2024-12-04 11:57:18,842] {logging_mixin.py:115} INFO - [2024-12-04 11:57:18,842] {dagbag.py:508} INFO - Filling up the DagBag from /home/airflow/dags/Lead_scoring_inference_pipeline/lead_scoring_inference_pipeline.py
[2024-12-04 11:57:18,851] {logging_mixin.py:115} INFO - [2024-12-04 11:57:18,850] {dagbag.py:321} ERROR - Failed to import: /home/airflow/dags/Lead_scoring_inference_pipeline/lead_scoring_inference_pipeline.py
Traceback (most recent call last):
  File "/opt/conda/lib/python3.8/site-packages/airflow/models/dagbag.py", line 318, in parse
    loader.exec_module(new_module)
  File "<frozen importlib._bootstrap_external>", line 843, in exec_module
  File "<frozen importlib._bootstrap>", line 219, in _call_with_frames_removed
  File "/home/airflow/dags/Lead_scoring_inference_pipeline/lead_scoring_inference_pipeline.py", line 36, in <module>
    utils = module_from_file("utils", "airflow/dags/Lead_scoring_inference_pipeline/utils.py")
  File "/home/airflow/dags/Lead_scoring_inference_pipeline/lead_scoring_inference_pipeline.py", line 33, in module_from_file
    spec.loader.exec_module(module)
  File "<frozen importlib._bootstrap_external>", line 839, in exec_module
  File "<frozen importlib._bootstrap_external>", line 975, in get_code
  File "<frozen importlib._bootstrap_external>", line 1032, in get_data
FileNotFoundError: [Errno 2] No such file or directory: 'airflow/dags/Lead_scoring_inference_pipeline/utils.py'
[2024-12-04 11:57:18,851] {processor.py:653} WARNING - No viable dags retrieved from /home/airflow/dags/Lead_scoring_inference_pipeline/lead_scoring_inference_pipeline.py
[2024-12-04 11:57:18,876] {processor.py:161} INFO - Processing /home/airflow/dags/Lead_scoring_inference_pipeline/lead_scoring_inference_pipeline.py took 0.039 seconds
[2024-12-04 11:57:54,764] {processor.py:153} INFO - Started process (PID=7684) to work on /home/airflow/dags/Lead_scoring_inference_pipeline/lead_scoring_inference_pipeline.py
[2024-12-04 11:57:54,765] {processor.py:641} INFO - Processing file /home/airflow/dags/Lead_scoring_inference_pipeline/lead_scoring_inference_pipeline.py for tasks to queue
[2024-12-04 11:57:54,766] {logging_mixin.py:115} INFO - [2024-12-04 11:57:54,766] {dagbag.py:508} INFO - Filling up the DagBag from /home/airflow/dags/Lead_scoring_inference_pipeline/lead_scoring_inference_pipeline.py
[2024-12-04 11:57:54,773] {logging_mixin.py:115} INFO - [2024-12-04 11:57:54,773] {dagbag.py:321} ERROR - Failed to import: /home/airflow/dags/Lead_scoring_inference_pipeline/lead_scoring_inference_pipeline.py
Traceback (most recent call last):
  File "/opt/conda/lib/python3.8/site-packages/airflow/models/dagbag.py", line 318, in parse
    loader.exec_module(new_module)
  File "<frozen importlib._bootstrap_external>", line 843, in exec_module
  File "<frozen importlib._bootstrap>", line 219, in _call_with_frames_removed
  File "/home/airflow/dags/Lead_scoring_inference_pipeline/lead_scoring_inference_pipeline.py", line 36, in <module>
    utils = module_from_file("utils", "airflow/dags/Lead_scoring_inference_pipeline/utils.py")
  File "/home/airflow/dags/Lead_scoring_inference_pipeline/lead_scoring_inference_pipeline.py", line 33, in module_from_file
    spec.loader.exec_module(module)
  File "<frozen importlib._bootstrap_external>", line 839, in exec_module
  File "<frozen importlib._bootstrap_external>", line 975, in get_code
  File "<frozen importlib._bootstrap_external>", line 1032, in get_data
FileNotFoundError: [Errno 2] No such file or directory: 'airflow/dags/Lead_scoring_inference_pipeline/utils.py'
[2024-12-04 11:57:54,774] {processor.py:653} WARNING - No viable dags retrieved from /home/airflow/dags/Lead_scoring_inference_pipeline/lead_scoring_inference_pipeline.py
[2024-12-04 11:57:54,797] {processor.py:161} INFO - Processing /home/airflow/dags/Lead_scoring_inference_pipeline/lead_scoring_inference_pipeline.py took 0.036 seconds
[2024-12-04 11:58:27,041] {processor.py:153} INFO - Started process (PID=7731) to work on /home/airflow/dags/Lead_scoring_inference_pipeline/lead_scoring_inference_pipeline.py
[2024-12-04 11:58:27,043] {processor.py:641} INFO - Processing file /home/airflow/dags/Lead_scoring_inference_pipeline/lead_scoring_inference_pipeline.py for tasks to queue
[2024-12-04 11:58:27,043] {logging_mixin.py:115} INFO - [2024-12-04 11:58:27,043] {dagbag.py:508} INFO - Filling up the DagBag from /home/airflow/dags/Lead_scoring_inference_pipeline/lead_scoring_inference_pipeline.py
[2024-12-04 11:58:27,051] {logging_mixin.py:115} INFO - [2024-12-04 11:58:27,051] {dagbag.py:321} ERROR - Failed to import: /home/airflow/dags/Lead_scoring_inference_pipeline/lead_scoring_inference_pipeline.py
Traceback (most recent call last):
  File "/opt/conda/lib/python3.8/site-packages/airflow/models/dagbag.py", line 318, in parse
    loader.exec_module(new_module)
  File "<frozen importlib._bootstrap_external>", line 843, in exec_module
  File "<frozen importlib._bootstrap>", line 219, in _call_with_frames_removed
  File "/home/airflow/dags/Lead_scoring_inference_pipeline/lead_scoring_inference_pipeline.py", line 36, in <module>
    utils = module_from_file("utils", "airflow/dags/Lead_scoring_inference_pipeline/utils.py")
  File "/home/airflow/dags/Lead_scoring_inference_pipeline/lead_scoring_inference_pipeline.py", line 33, in module_from_file
    spec.loader.exec_module(module)
  File "<frozen importlib._bootstrap_external>", line 839, in exec_module
  File "<frozen importlib._bootstrap_external>", line 975, in get_code
  File "<frozen importlib._bootstrap_external>", line 1032, in get_data
FileNotFoundError: [Errno 2] No such file or directory: 'airflow/dags/Lead_scoring_inference_pipeline/utils.py'
[2024-12-04 11:58:27,052] {processor.py:653} WARNING - No viable dags retrieved from /home/airflow/dags/Lead_scoring_inference_pipeline/lead_scoring_inference_pipeline.py
[2024-12-04 11:58:27,076] {processor.py:161} INFO - Processing /home/airflow/dags/Lead_scoring_inference_pipeline/lead_scoring_inference_pipeline.py took 0.039 seconds
[2024-12-04 11:59:03,242] {processor.py:153} INFO - Started process (PID=7796) to work on /home/airflow/dags/Lead_scoring_inference_pipeline/lead_scoring_inference_pipeline.py
[2024-12-04 11:59:03,244] {processor.py:641} INFO - Processing file /home/airflow/dags/Lead_scoring_inference_pipeline/lead_scoring_inference_pipeline.py for tasks to queue
[2024-12-04 11:59:03,244] {logging_mixin.py:115} INFO - [2024-12-04 11:59:03,244] {dagbag.py:508} INFO - Filling up the DagBag from /home/airflow/dags/Lead_scoring_inference_pipeline/lead_scoring_inference_pipeline.py
[2024-12-04 11:59:03,253] {logging_mixin.py:115} INFO - [2024-12-04 11:59:03,252] {dagbag.py:321} ERROR - Failed to import: /home/airflow/dags/Lead_scoring_inference_pipeline/lead_scoring_inference_pipeline.py
Traceback (most recent call last):
  File "/opt/conda/lib/python3.8/site-packages/airflow/models/dagbag.py", line 318, in parse
    loader.exec_module(new_module)
  File "<frozen importlib._bootstrap_external>", line 843, in exec_module
  File "<frozen importlib._bootstrap>", line 219, in _call_with_frames_removed
  File "/home/airflow/dags/Lead_scoring_inference_pipeline/lead_scoring_inference_pipeline.py", line 36, in <module>
    utils = module_from_file("utils", "airflow/dags/Lead_scoring_inference_pipeline/utils.py")
  File "/home/airflow/dags/Lead_scoring_inference_pipeline/lead_scoring_inference_pipeline.py", line 33, in module_from_file
    spec.loader.exec_module(module)
  File "<frozen importlib._bootstrap_external>", line 839, in exec_module
  File "<frozen importlib._bootstrap_external>", line 975, in get_code
  File "<frozen importlib._bootstrap_external>", line 1032, in get_data
FileNotFoundError: [Errno 2] No such file or directory: 'airflow/dags/Lead_scoring_inference_pipeline/utils.py'
[2024-12-04 11:59:03,253] {processor.py:653} WARNING - No viable dags retrieved from /home/airflow/dags/Lead_scoring_inference_pipeline/lead_scoring_inference_pipeline.py
[2024-12-04 11:59:03,278] {processor.py:161} INFO - Processing /home/airflow/dags/Lead_scoring_inference_pipeline/lead_scoring_inference_pipeline.py took 0.040 seconds
[2024-12-04 11:59:42,077] {processor.py:153} INFO - Started process (PID=7853) to work on /home/airflow/dags/Lead_scoring_inference_pipeline/lead_scoring_inference_pipeline.py
[2024-12-04 11:59:42,078] {processor.py:641} INFO - Processing file /home/airflow/dags/Lead_scoring_inference_pipeline/lead_scoring_inference_pipeline.py for tasks to queue
[2024-12-04 11:59:42,079] {logging_mixin.py:115} INFO - [2024-12-04 11:59:42,079] {dagbag.py:508} INFO - Filling up the DagBag from /home/airflow/dags/Lead_scoring_inference_pipeline/lead_scoring_inference_pipeline.py
[2024-12-04 11:59:42,087] {logging_mixin.py:115} INFO - [2024-12-04 11:59:42,086] {dagbag.py:321} ERROR - Failed to import: /home/airflow/dags/Lead_scoring_inference_pipeline/lead_scoring_inference_pipeline.py
Traceback (most recent call last):
  File "/opt/conda/lib/python3.8/site-packages/airflow/models/dagbag.py", line 318, in parse
    loader.exec_module(new_module)
  File "<frozen importlib._bootstrap_external>", line 843, in exec_module
  File "<frozen importlib._bootstrap>", line 219, in _call_with_frames_removed
  File "/home/airflow/dags/Lead_scoring_inference_pipeline/lead_scoring_inference_pipeline.py", line 36, in <module>
    utils = module_from_file("utils", "airflow/dags/Lead_scoring_inference_pipeline/utils.py")
  File "/home/airflow/dags/Lead_scoring_inference_pipeline/lead_scoring_inference_pipeline.py", line 33, in module_from_file
    spec.loader.exec_module(module)
  File "<frozen importlib._bootstrap_external>", line 839, in exec_module
  File "<frozen importlib._bootstrap_external>", line 975, in get_code
  File "<frozen importlib._bootstrap_external>", line 1032, in get_data
FileNotFoundError: [Errno 2] No such file or directory: 'airflow/dags/Lead_scoring_inference_pipeline/utils.py'
[2024-12-04 11:59:42,087] {processor.py:653} WARNING - No viable dags retrieved from /home/airflow/dags/Lead_scoring_inference_pipeline/lead_scoring_inference_pipeline.py
[2024-12-04 11:59:42,113] {processor.py:161} INFO - Processing /home/airflow/dags/Lead_scoring_inference_pipeline/lead_scoring_inference_pipeline.py took 0.039 seconds
[2024-12-04 12:00:17,908] {processor.py:153} INFO - Started process (PID=7903) to work on /home/airflow/dags/Lead_scoring_inference_pipeline/lead_scoring_inference_pipeline.py
[2024-12-04 12:00:17,909] {processor.py:641} INFO - Processing file /home/airflow/dags/Lead_scoring_inference_pipeline/lead_scoring_inference_pipeline.py for tasks to queue
[2024-12-04 12:00:17,910] {logging_mixin.py:115} INFO - [2024-12-04 12:00:17,910] {dagbag.py:508} INFO - Filling up the DagBag from /home/airflow/dags/Lead_scoring_inference_pipeline/lead_scoring_inference_pipeline.py
[2024-12-04 12:00:17,918] {logging_mixin.py:115} INFO - [2024-12-04 12:00:17,917] {dagbag.py:321} ERROR - Failed to import: /home/airflow/dags/Lead_scoring_inference_pipeline/lead_scoring_inference_pipeline.py
Traceback (most recent call last):
  File "/opt/conda/lib/python3.8/site-packages/airflow/models/dagbag.py", line 318, in parse
    loader.exec_module(new_module)
  File "<frozen importlib._bootstrap_external>", line 843, in exec_module
  File "<frozen importlib._bootstrap>", line 219, in _call_with_frames_removed
  File "/home/airflow/dags/Lead_scoring_inference_pipeline/lead_scoring_inference_pipeline.py", line 36, in <module>
    utils = module_from_file("utils", "airflow/dags/Lead_scoring_inference_pipeline/utils.py")
  File "/home/airflow/dags/Lead_scoring_inference_pipeline/lead_scoring_inference_pipeline.py", line 33, in module_from_file
    spec.loader.exec_module(module)
  File "<frozen importlib._bootstrap_external>", line 839, in exec_module
  File "<frozen importlib._bootstrap_external>", line 975, in get_code
  File "<frozen importlib._bootstrap_external>", line 1032, in get_data
FileNotFoundError: [Errno 2] No such file or directory: 'airflow/dags/Lead_scoring_inference_pipeline/utils.py'
[2024-12-04 12:00:17,918] {processor.py:653} WARNING - No viable dags retrieved from /home/airflow/dags/Lead_scoring_inference_pipeline/lead_scoring_inference_pipeline.py
[2024-12-04 12:00:17,943] {processor.py:161} INFO - Processing /home/airflow/dags/Lead_scoring_inference_pipeline/lead_scoring_inference_pipeline.py took 0.038 seconds
[2024-12-04 12:00:54,693] {processor.py:153} INFO - Started process (PID=7954) to work on /home/airflow/dags/Lead_scoring_inference_pipeline/lead_scoring_inference_pipeline.py
[2024-12-04 12:00:54,694] {processor.py:641} INFO - Processing file /home/airflow/dags/Lead_scoring_inference_pipeline/lead_scoring_inference_pipeline.py for tasks to queue
[2024-12-04 12:00:54,695] {logging_mixin.py:115} INFO - [2024-12-04 12:00:54,695] {dagbag.py:508} INFO - Filling up the DagBag from /home/airflow/dags/Lead_scoring_inference_pipeline/lead_scoring_inference_pipeline.py
[2024-12-04 12:00:54,703] {logging_mixin.py:115} INFO - [2024-12-04 12:00:54,702] {dagbag.py:321} ERROR - Failed to import: /home/airflow/dags/Lead_scoring_inference_pipeline/lead_scoring_inference_pipeline.py
Traceback (most recent call last):
  File "/opt/conda/lib/python3.8/site-packages/airflow/models/dagbag.py", line 318, in parse
    loader.exec_module(new_module)
  File "<frozen importlib._bootstrap_external>", line 843, in exec_module
  File "<frozen importlib._bootstrap>", line 219, in _call_with_frames_removed
  File "/home/airflow/dags/Lead_scoring_inference_pipeline/lead_scoring_inference_pipeline.py", line 36, in <module>
    utils = module_from_file("utils", "airflow/dags/Lead_scoring_inference_pipeline/utils.py")
  File "/home/airflow/dags/Lead_scoring_inference_pipeline/lead_scoring_inference_pipeline.py", line 33, in module_from_file
    spec.loader.exec_module(module)
  File "<frozen importlib._bootstrap_external>", line 839, in exec_module
  File "<frozen importlib._bootstrap_external>", line 975, in get_code
  File "<frozen importlib._bootstrap_external>", line 1032, in get_data
FileNotFoundError: [Errno 2] No such file or directory: 'airflow/dags/Lead_scoring_inference_pipeline/utils.py'
[2024-12-04 12:00:54,703] {processor.py:653} WARNING - No viable dags retrieved from /home/airflow/dags/Lead_scoring_inference_pipeline/lead_scoring_inference_pipeline.py
[2024-12-04 12:00:54,728] {processor.py:161} INFO - Processing /home/airflow/dags/Lead_scoring_inference_pipeline/lead_scoring_inference_pipeline.py took 0.039 seconds
[2024-12-04 12:01:34,825] {processor.py:153} INFO - Started process (PID=8007) to work on /home/airflow/dags/Lead_scoring_inference_pipeline/lead_scoring_inference_pipeline.py
[2024-12-04 12:01:34,826] {processor.py:641} INFO - Processing file /home/airflow/dags/Lead_scoring_inference_pipeline/lead_scoring_inference_pipeline.py for tasks to queue
[2024-12-04 12:01:34,827] {logging_mixin.py:115} INFO - [2024-12-04 12:01:34,827] {dagbag.py:508} INFO - Filling up the DagBag from /home/airflow/dags/Lead_scoring_inference_pipeline/lead_scoring_inference_pipeline.py
[2024-12-04 12:01:34,835] {logging_mixin.py:115} INFO - [2024-12-04 12:01:34,835] {dagbag.py:321} ERROR - Failed to import: /home/airflow/dags/Lead_scoring_inference_pipeline/lead_scoring_inference_pipeline.py
Traceback (most recent call last):
  File "/opt/conda/lib/python3.8/site-packages/airflow/models/dagbag.py", line 318, in parse
    loader.exec_module(new_module)
  File "<frozen importlib._bootstrap_external>", line 843, in exec_module
  File "<frozen importlib._bootstrap>", line 219, in _call_with_frames_removed
  File "/home/airflow/dags/Lead_scoring_inference_pipeline/lead_scoring_inference_pipeline.py", line 36, in <module>
    utils = module_from_file("utils", "airflow/dags/Lead_scoring_inference_pipeline/utils.py")
  File "/home/airflow/dags/Lead_scoring_inference_pipeline/lead_scoring_inference_pipeline.py", line 33, in module_from_file
    spec.loader.exec_module(module)
  File "<frozen importlib._bootstrap_external>", line 839, in exec_module
  File "<frozen importlib._bootstrap_external>", line 975, in get_code
  File "<frozen importlib._bootstrap_external>", line 1032, in get_data
FileNotFoundError: [Errno 2] No such file or directory: 'airflow/dags/Lead_scoring_inference_pipeline/utils.py'
[2024-12-04 12:01:34,836] {processor.py:653} WARNING - No viable dags retrieved from /home/airflow/dags/Lead_scoring_inference_pipeline/lead_scoring_inference_pipeline.py
[2024-12-04 12:01:34,863] {processor.py:161} INFO - Processing /home/airflow/dags/Lead_scoring_inference_pipeline/lead_scoring_inference_pipeline.py took 0.042 seconds
[2024-12-04 12:02:10,574] {processor.py:153} INFO - Started process (PID=8058) to work on /home/airflow/dags/Lead_scoring_inference_pipeline/lead_scoring_inference_pipeline.py
[2024-12-04 12:02:10,575] {processor.py:641} INFO - Processing file /home/airflow/dags/Lead_scoring_inference_pipeline/lead_scoring_inference_pipeline.py for tasks to queue
[2024-12-04 12:02:10,576] {logging_mixin.py:115} INFO - [2024-12-04 12:02:10,576] {dagbag.py:508} INFO - Filling up the DagBag from /home/airflow/dags/Lead_scoring_inference_pipeline/lead_scoring_inference_pipeline.py
[2024-12-04 12:02:10,584] {logging_mixin.py:115} INFO - [2024-12-04 12:02:10,583] {dagbag.py:321} ERROR - Failed to import: /home/airflow/dags/Lead_scoring_inference_pipeline/lead_scoring_inference_pipeline.py
Traceback (most recent call last):
  File "/opt/conda/lib/python3.8/site-packages/airflow/models/dagbag.py", line 318, in parse
    loader.exec_module(new_module)
  File "<frozen importlib._bootstrap_external>", line 843, in exec_module
  File "<frozen importlib._bootstrap>", line 219, in _call_with_frames_removed
  File "/home/airflow/dags/Lead_scoring_inference_pipeline/lead_scoring_inference_pipeline.py", line 36, in <module>
    utils = module_from_file("utils", "airflow/dags/Lead_scoring_inference_pipeline/utils.py")
  File "/home/airflow/dags/Lead_scoring_inference_pipeline/lead_scoring_inference_pipeline.py", line 33, in module_from_file
    spec.loader.exec_module(module)
  File "<frozen importlib._bootstrap_external>", line 839, in exec_module
  File "<frozen importlib._bootstrap_external>", line 975, in get_code
  File "<frozen importlib._bootstrap_external>", line 1032, in get_data
FileNotFoundError: [Errno 2] No such file or directory: 'airflow/dags/Lead_scoring_inference_pipeline/utils.py'
[2024-12-04 12:02:10,584] {processor.py:653} WARNING - No viable dags retrieved from /home/airflow/dags/Lead_scoring_inference_pipeline/lead_scoring_inference_pipeline.py
[2024-12-04 12:02:10,610] {processor.py:161} INFO - Processing /home/airflow/dags/Lead_scoring_inference_pipeline/lead_scoring_inference_pipeline.py took 0.040 seconds
[2024-12-04 12:02:50,007] {processor.py:153} INFO - Started process (PID=8110) to work on /home/airflow/dags/Lead_scoring_inference_pipeline/lead_scoring_inference_pipeline.py
[2024-12-04 12:02:50,009] {processor.py:641} INFO - Processing file /home/airflow/dags/Lead_scoring_inference_pipeline/lead_scoring_inference_pipeline.py for tasks to queue
[2024-12-04 12:02:50,009] {logging_mixin.py:115} INFO - [2024-12-04 12:02:50,009] {dagbag.py:508} INFO - Filling up the DagBag from /home/airflow/dags/Lead_scoring_inference_pipeline/lead_scoring_inference_pipeline.py
[2024-12-04 12:02:50,017] {logging_mixin.py:115} INFO - [2024-12-04 12:02:50,017] {dagbag.py:321} ERROR - Failed to import: /home/airflow/dags/Lead_scoring_inference_pipeline/lead_scoring_inference_pipeline.py
Traceback (most recent call last):
  File "/opt/conda/lib/python3.8/site-packages/airflow/models/dagbag.py", line 318, in parse
    loader.exec_module(new_module)
  File "<frozen importlib._bootstrap_external>", line 843, in exec_module
  File "<frozen importlib._bootstrap>", line 219, in _call_with_frames_removed
  File "/home/airflow/dags/Lead_scoring_inference_pipeline/lead_scoring_inference_pipeline.py", line 36, in <module>
    utils = module_from_file("utils", "airflow/dags/Lead_scoring_inference_pipeline/utils.py")
  File "/home/airflow/dags/Lead_scoring_inference_pipeline/lead_scoring_inference_pipeline.py", line 33, in module_from_file
    spec.loader.exec_module(module)
  File "<frozen importlib._bootstrap_external>", line 839, in exec_module
  File "<frozen importlib._bootstrap_external>", line 975, in get_code
  File "<frozen importlib._bootstrap_external>", line 1032, in get_data
FileNotFoundError: [Errno 2] No such file or directory: 'airflow/dags/Lead_scoring_inference_pipeline/utils.py'
[2024-12-04 12:02:50,018] {processor.py:653} WARNING - No viable dags retrieved from /home/airflow/dags/Lead_scoring_inference_pipeline/lead_scoring_inference_pipeline.py
[2024-12-04 12:02:50,044] {processor.py:161} INFO - Processing /home/airflow/dags/Lead_scoring_inference_pipeline/lead_scoring_inference_pipeline.py took 0.040 seconds
[2024-12-04 12:03:34,016] {processor.py:153} INFO - Started process (PID=8167) to work on /home/airflow/dags/Lead_scoring_inference_pipeline/lead_scoring_inference_pipeline.py
[2024-12-04 12:03:34,017] {processor.py:641} INFO - Processing file /home/airflow/dags/Lead_scoring_inference_pipeline/lead_scoring_inference_pipeline.py for tasks to queue
[2024-12-04 12:03:34,018] {logging_mixin.py:115} INFO - [2024-12-04 12:03:34,018] {dagbag.py:508} INFO - Filling up the DagBag from /home/airflow/dags/Lead_scoring_inference_pipeline/lead_scoring_inference_pipeline.py
[2024-12-04 12:03:34,026] {logging_mixin.py:115} INFO - [2024-12-04 12:03:34,025] {dagbag.py:321} ERROR - Failed to import: /home/airflow/dags/Lead_scoring_inference_pipeline/lead_scoring_inference_pipeline.py
Traceback (most recent call last):
  File "/opt/conda/lib/python3.8/site-packages/airflow/models/dagbag.py", line 318, in parse
    loader.exec_module(new_module)
  File "<frozen importlib._bootstrap_external>", line 843, in exec_module
  File "<frozen importlib._bootstrap>", line 219, in _call_with_frames_removed
  File "/home/airflow/dags/Lead_scoring_inference_pipeline/lead_scoring_inference_pipeline.py", line 36, in <module>
    utils = module_from_file("utils", "airflow/dags/Lead_scoring_inference_pipeline/utils.py")
  File "/home/airflow/dags/Lead_scoring_inference_pipeline/lead_scoring_inference_pipeline.py", line 33, in module_from_file
    spec.loader.exec_module(module)
  File "<frozen importlib._bootstrap_external>", line 839, in exec_module
  File "<frozen importlib._bootstrap_external>", line 975, in get_code
  File "<frozen importlib._bootstrap_external>", line 1032, in get_data
FileNotFoundError: [Errno 2] No such file or directory: 'airflow/dags/Lead_scoring_inference_pipeline/utils.py'
[2024-12-04 12:03:34,026] {processor.py:653} WARNING - No viable dags retrieved from /home/airflow/dags/Lead_scoring_inference_pipeline/lead_scoring_inference_pipeline.py
[2024-12-04 12:03:34,053] {processor.py:161} INFO - Processing /home/airflow/dags/Lead_scoring_inference_pipeline/lead_scoring_inference_pipeline.py took 0.041 seconds
[2024-12-04 12:03:59,514] {processor.py:153} INFO - Started process (PID=8207) to work on /home/airflow/dags/Lead_scoring_inference_pipeline/lead_scoring_inference_pipeline.py
[2024-12-04 12:03:59,515] {processor.py:641} INFO - Processing file /home/airflow/dags/Lead_scoring_inference_pipeline/lead_scoring_inference_pipeline.py for tasks to queue
[2024-12-04 12:03:59,515] {logging_mixin.py:115} INFO - [2024-12-04 12:03:59,515] {dagbag.py:508} INFO - Filling up the DagBag from /home/airflow/dags/Lead_scoring_inference_pipeline/lead_scoring_inference_pipeline.py
[2024-12-04 12:03:59,525] {logging_mixin.py:115} INFO - [2024-12-04 12:03:59,524] {dagbag.py:321} ERROR - Failed to import: /home/airflow/dags/Lead_scoring_inference_pipeline/lead_scoring_inference_pipeline.py
Traceback (most recent call last):
  File "/opt/conda/lib/python3.8/site-packages/airflow/models/dagbag.py", line 318, in parse
    loader.exec_module(new_module)
  File "<frozen importlib._bootstrap_external>", line 843, in exec_module
  File "<frozen importlib._bootstrap>", line 219, in _call_with_frames_removed
  File "/home/airflow/dags/Lead_scoring_inference_pipeline/lead_scoring_inference_pipeline.py", line 36, in <module>
    utils = module_from_file("utils", "/airflow/dags/Lead_scoring_inference_pipeline/utils.py")
  File "/home/airflow/dags/Lead_scoring_inference_pipeline/lead_scoring_inference_pipeline.py", line 33, in module_from_file
    spec.loader.exec_module(module)
  File "<frozen importlib._bootstrap_external>", line 839, in exec_module
  File "<frozen importlib._bootstrap_external>", line 975, in get_code
  File "<frozen importlib._bootstrap_external>", line 1032, in get_data
FileNotFoundError: [Errno 2] No such file or directory: '/airflow/dags/Lead_scoring_inference_pipeline/utils.py'
[2024-12-04 12:03:59,525] {processor.py:653} WARNING - No viable dags retrieved from /home/airflow/dags/Lead_scoring_inference_pipeline/lead_scoring_inference_pipeline.py
[2024-12-04 12:03:59,558] {processor.py:161} INFO - Processing /home/airflow/dags/Lead_scoring_inference_pipeline/lead_scoring_inference_pipeline.py took 0.047 seconds
[2024-12-04 12:04:40,005] {processor.py:153} INFO - Started process (PID=8261) to work on /home/airflow/dags/Lead_scoring_inference_pipeline/lead_scoring_inference_pipeline.py
[2024-12-04 12:04:40,007] {processor.py:641} INFO - Processing file /home/airflow/dags/Lead_scoring_inference_pipeline/lead_scoring_inference_pipeline.py for tasks to queue
[2024-12-04 12:04:40,007] {logging_mixin.py:115} INFO - [2024-12-04 12:04:40,007] {dagbag.py:508} INFO - Filling up the DagBag from /home/airflow/dags/Lead_scoring_inference_pipeline/lead_scoring_inference_pipeline.py
[2024-12-04 12:04:40,016] {logging_mixin.py:115} INFO - [2024-12-04 12:04:40,015] {dagbag.py:321} ERROR - Failed to import: /home/airflow/dags/Lead_scoring_inference_pipeline/lead_scoring_inference_pipeline.py
Traceback (most recent call last):
  File "/opt/conda/lib/python3.8/site-packages/airflow/models/dagbag.py", line 318, in parse
    loader.exec_module(new_module)
  File "<frozen importlib._bootstrap_external>", line 843, in exec_module
  File "<frozen importlib._bootstrap>", line 219, in _call_with_frames_removed
  File "/home/airflow/dags/Lead_scoring_inference_pipeline/lead_scoring_inference_pipeline.py", line 36, in <module>
    utils = module_from_file("utils", "/airflow/dags/Lead_scoring_inference_pipeline/utils.py")
  File "/home/airflow/dags/Lead_scoring_inference_pipeline/lead_scoring_inference_pipeline.py", line 33, in module_from_file
    spec.loader.exec_module(module)
  File "<frozen importlib._bootstrap_external>", line 839, in exec_module
  File "<frozen importlib._bootstrap_external>", line 975, in get_code
  File "<frozen importlib._bootstrap_external>", line 1032, in get_data
FileNotFoundError: [Errno 2] No such file or directory: '/airflow/dags/Lead_scoring_inference_pipeline/utils.py'
[2024-12-04 12:04:40,016] {processor.py:653} WARNING - No viable dags retrieved from /home/airflow/dags/Lead_scoring_inference_pipeline/lead_scoring_inference_pipeline.py
[2024-12-04 12:04:40,041] {processor.py:161} INFO - Processing /home/airflow/dags/Lead_scoring_inference_pipeline/lead_scoring_inference_pipeline.py took 0.040 seconds
[2024-12-04 12:05:16,849] {processor.py:153} INFO - Started process (PID=8311) to work on /home/airflow/dags/Lead_scoring_inference_pipeline/lead_scoring_inference_pipeline.py
[2024-12-04 12:05:16,850] {processor.py:641} INFO - Processing file /home/airflow/dags/Lead_scoring_inference_pipeline/lead_scoring_inference_pipeline.py for tasks to queue
[2024-12-04 12:05:16,851] {logging_mixin.py:115} INFO - [2024-12-04 12:05:16,851] {dagbag.py:508} INFO - Filling up the DagBag from /home/airflow/dags/Lead_scoring_inference_pipeline/lead_scoring_inference_pipeline.py
[2024-12-04 12:05:16,859] {logging_mixin.py:115} INFO - [2024-12-04 12:05:16,858] {dagbag.py:321} ERROR - Failed to import: /home/airflow/dags/Lead_scoring_inference_pipeline/lead_scoring_inference_pipeline.py
Traceback (most recent call last):
  File "/opt/conda/lib/python3.8/site-packages/airflow/models/dagbag.py", line 318, in parse
    loader.exec_module(new_module)
  File "<frozen importlib._bootstrap_external>", line 843, in exec_module
  File "<frozen importlib._bootstrap>", line 219, in _call_with_frames_removed
  File "/home/airflow/dags/Lead_scoring_inference_pipeline/lead_scoring_inference_pipeline.py", line 36, in <module>
    utils = module_from_file("utils", "/airflow/dags/Lead_scoring_inference_pipeline/utils.py")
  File "/home/airflow/dags/Lead_scoring_inference_pipeline/lead_scoring_inference_pipeline.py", line 33, in module_from_file
    spec.loader.exec_module(module)
  File "<frozen importlib._bootstrap_external>", line 839, in exec_module
  File "<frozen importlib._bootstrap_external>", line 975, in get_code
  File "<frozen importlib._bootstrap_external>", line 1032, in get_data
FileNotFoundError: [Errno 2] No such file or directory: '/airflow/dags/Lead_scoring_inference_pipeline/utils.py'
[2024-12-04 12:05:16,859] {processor.py:653} WARNING - No viable dags retrieved from /home/airflow/dags/Lead_scoring_inference_pipeline/lead_scoring_inference_pipeline.py
[2024-12-04 12:05:16,883] {processor.py:161} INFO - Processing /home/airflow/dags/Lead_scoring_inference_pipeline/lead_scoring_inference_pipeline.py took 0.038 seconds
[2024-12-04 12:05:58,905] {processor.py:153} INFO - Started process (PID=8366) to work on /home/airflow/dags/Lead_scoring_inference_pipeline/lead_scoring_inference_pipeline.py
[2024-12-04 12:05:58,906] {processor.py:641} INFO - Processing file /home/airflow/dags/Lead_scoring_inference_pipeline/lead_scoring_inference_pipeline.py for tasks to queue
[2024-12-04 12:05:58,907] {logging_mixin.py:115} INFO - [2024-12-04 12:05:58,907] {dagbag.py:508} INFO - Filling up the DagBag from /home/airflow/dags/Lead_scoring_inference_pipeline/lead_scoring_inference_pipeline.py
[2024-12-04 12:05:58,915] {logging_mixin.py:115} INFO - [2024-12-04 12:05:58,914] {dagbag.py:321} ERROR - Failed to import: /home/airflow/dags/Lead_scoring_inference_pipeline/lead_scoring_inference_pipeline.py
Traceback (most recent call last):
  File "/opt/conda/lib/python3.8/site-packages/airflow/models/dagbag.py", line 318, in parse
    loader.exec_module(new_module)
  File "<frozen importlib._bootstrap_external>", line 843, in exec_module
  File "<frozen importlib._bootstrap>", line 219, in _call_with_frames_removed
  File "/home/airflow/dags/Lead_scoring_inference_pipeline/lead_scoring_inference_pipeline.py", line 36, in <module>
    utils = module_from_file("utils", "/airflow/dags/Lead_scoring_inference_pipeline/utils.py")
  File "/home/airflow/dags/Lead_scoring_inference_pipeline/lead_scoring_inference_pipeline.py", line 33, in module_from_file
    spec.loader.exec_module(module)
  File "<frozen importlib._bootstrap_external>", line 839, in exec_module
  File "<frozen importlib._bootstrap_external>", line 975, in get_code
  File "<frozen importlib._bootstrap_external>", line 1032, in get_data
FileNotFoundError: [Errno 2] No such file or directory: '/airflow/dags/Lead_scoring_inference_pipeline/utils.py'
[2024-12-04 12:05:58,915] {processor.py:653} WARNING - No viable dags retrieved from /home/airflow/dags/Lead_scoring_inference_pipeline/lead_scoring_inference_pipeline.py
[2024-12-04 12:05:58,940] {processor.py:161} INFO - Processing /home/airflow/dags/Lead_scoring_inference_pipeline/lead_scoring_inference_pipeline.py took 0.038 seconds
[2024-12-04 12:06:38,329] {processor.py:153} INFO - Started process (PID=8422) to work on /home/airflow/dags/Lead_scoring_inference_pipeline/lead_scoring_inference_pipeline.py
[2024-12-04 12:06:38,330] {processor.py:641} INFO - Processing file /home/airflow/dags/Lead_scoring_inference_pipeline/lead_scoring_inference_pipeline.py for tasks to queue
[2024-12-04 12:06:38,331] {logging_mixin.py:115} INFO - [2024-12-04 12:06:38,330] {dagbag.py:508} INFO - Filling up the DagBag from /home/airflow/dags/Lead_scoring_inference_pipeline/lead_scoring_inference_pipeline.py
[2024-12-04 12:06:38,339] {logging_mixin.py:115} INFO - [2024-12-04 12:06:38,338] {dagbag.py:321} ERROR - Failed to import: /home/airflow/dags/Lead_scoring_inference_pipeline/lead_scoring_inference_pipeline.py
Traceback (most recent call last):
  File "/opt/conda/lib/python3.8/site-packages/airflow/models/dagbag.py", line 318, in parse
    loader.exec_module(new_module)
  File "<frozen importlib._bootstrap_external>", line 843, in exec_module
  File "<frozen importlib._bootstrap>", line 219, in _call_with_frames_removed
  File "/home/airflow/dags/Lead_scoring_inference_pipeline/lead_scoring_inference_pipeline.py", line 36, in <module>
    utils = module_from_file("utils", "/airflow/dags/Lead_scoring_inference_pipeline/utils.py")
  File "/home/airflow/dags/Lead_scoring_inference_pipeline/lead_scoring_inference_pipeline.py", line 33, in module_from_file
    spec.loader.exec_module(module)
  File "<frozen importlib._bootstrap_external>", line 839, in exec_module
  File "<frozen importlib._bootstrap_external>", line 975, in get_code
  File "<frozen importlib._bootstrap_external>", line 1032, in get_data
FileNotFoundError: [Errno 2] No such file or directory: '/airflow/dags/Lead_scoring_inference_pipeline/utils.py'
[2024-12-04 12:06:38,339] {processor.py:653} WARNING - No viable dags retrieved from /home/airflow/dags/Lead_scoring_inference_pipeline/lead_scoring_inference_pipeline.py
[2024-12-04 12:06:38,365] {processor.py:161} INFO - Processing /home/airflow/dags/Lead_scoring_inference_pipeline/lead_scoring_inference_pipeline.py took 0.040 seconds
[2024-12-04 12:07:17,680] {processor.py:153} INFO - Started process (PID=8480) to work on /home/airflow/dags/Lead_scoring_inference_pipeline/lead_scoring_inference_pipeline.py
[2024-12-04 12:07:17,682] {processor.py:641} INFO - Processing file /home/airflow/dags/Lead_scoring_inference_pipeline/lead_scoring_inference_pipeline.py for tasks to queue
[2024-12-04 12:07:17,682] {logging_mixin.py:115} INFO - [2024-12-04 12:07:17,682] {dagbag.py:508} INFO - Filling up the DagBag from /home/airflow/dags/Lead_scoring_inference_pipeline/lead_scoring_inference_pipeline.py
[2024-12-04 12:07:17,690] {logging_mixin.py:115} INFO - [2024-12-04 12:07:17,689] {dagbag.py:321} ERROR - Failed to import: /home/airflow/dags/Lead_scoring_inference_pipeline/lead_scoring_inference_pipeline.py
Traceback (most recent call last):
  File "/opt/conda/lib/python3.8/site-packages/airflow/models/dagbag.py", line 318, in parse
    loader.exec_module(new_module)
  File "<frozen importlib._bootstrap_external>", line 843, in exec_module
  File "<frozen importlib._bootstrap>", line 219, in _call_with_frames_removed
  File "/home/airflow/dags/Lead_scoring_inference_pipeline/lead_scoring_inference_pipeline.py", line 36, in <module>
    utils = module_from_file("utils", "/airflow/dags/Lead_scoring_inference_pipeline/utils.py")
  File "/home/airflow/dags/Lead_scoring_inference_pipeline/lead_scoring_inference_pipeline.py", line 33, in module_from_file
    spec.loader.exec_module(module)
  File "<frozen importlib._bootstrap_external>", line 839, in exec_module
  File "<frozen importlib._bootstrap_external>", line 975, in get_code
  File "<frozen importlib._bootstrap_external>", line 1032, in get_data
FileNotFoundError: [Errno 2] No such file or directory: '/airflow/dags/Lead_scoring_inference_pipeline/utils.py'
[2024-12-04 12:07:17,690] {processor.py:653} WARNING - No viable dags retrieved from /home/airflow/dags/Lead_scoring_inference_pipeline/lead_scoring_inference_pipeline.py
[2024-12-04 12:07:17,716] {processor.py:161} INFO - Processing /home/airflow/dags/Lead_scoring_inference_pipeline/lead_scoring_inference_pipeline.py took 0.039 seconds
[2024-12-04 12:07:56,416] {processor.py:153} INFO - Started process (PID=8533) to work on /home/airflow/dags/Lead_scoring_inference_pipeline/lead_scoring_inference_pipeline.py
[2024-12-04 12:07:56,418] {processor.py:641} INFO - Processing file /home/airflow/dags/Lead_scoring_inference_pipeline/lead_scoring_inference_pipeline.py for tasks to queue
[2024-12-04 12:07:56,418] {logging_mixin.py:115} INFO - [2024-12-04 12:07:56,418] {dagbag.py:508} INFO - Filling up the DagBag from /home/airflow/dags/Lead_scoring_inference_pipeline/lead_scoring_inference_pipeline.py
[2024-12-04 12:07:56,426] {logging_mixin.py:115} INFO - [2024-12-04 12:07:56,425] {dagbag.py:321} ERROR - Failed to import: /home/airflow/dags/Lead_scoring_inference_pipeline/lead_scoring_inference_pipeline.py
Traceback (most recent call last):
  File "/opt/conda/lib/python3.8/site-packages/airflow/models/dagbag.py", line 318, in parse
    loader.exec_module(new_module)
  File "<frozen importlib._bootstrap_external>", line 843, in exec_module
  File "<frozen importlib._bootstrap>", line 219, in _call_with_frames_removed
  File "/home/airflow/dags/Lead_scoring_inference_pipeline/lead_scoring_inference_pipeline.py", line 36, in <module>
    utils = module_from_file("utils", "/airflow/dags/Lead_scoring_inference_pipeline/utils.py")
  File "/home/airflow/dags/Lead_scoring_inference_pipeline/lead_scoring_inference_pipeline.py", line 33, in module_from_file
    spec.loader.exec_module(module)
  File "<frozen importlib._bootstrap_external>", line 839, in exec_module
  File "<frozen importlib._bootstrap_external>", line 975, in get_code
  File "<frozen importlib._bootstrap_external>", line 1032, in get_data
FileNotFoundError: [Errno 2] No such file or directory: '/airflow/dags/Lead_scoring_inference_pipeline/utils.py'
[2024-12-04 12:07:56,426] {processor.py:653} WARNING - No viable dags retrieved from /home/airflow/dags/Lead_scoring_inference_pipeline/lead_scoring_inference_pipeline.py
[2024-12-04 12:07:56,453] {processor.py:161} INFO - Processing /home/airflow/dags/Lead_scoring_inference_pipeline/lead_scoring_inference_pipeline.py took 0.040 seconds
[2024-12-04 12:08:33,161] {processor.py:153} INFO - Started process (PID=8583) to work on /home/airflow/dags/Lead_scoring_inference_pipeline/lead_scoring_inference_pipeline.py
[2024-12-04 12:08:33,162] {processor.py:641} INFO - Processing file /home/airflow/dags/Lead_scoring_inference_pipeline/lead_scoring_inference_pipeline.py for tasks to queue
[2024-12-04 12:08:33,163] {logging_mixin.py:115} INFO - [2024-12-04 12:08:33,163] {dagbag.py:508} INFO - Filling up the DagBag from /home/airflow/dags/Lead_scoring_inference_pipeline/lead_scoring_inference_pipeline.py
[2024-12-04 12:08:33,171] {logging_mixin.py:115} INFO - [2024-12-04 12:08:33,170] {dagbag.py:321} ERROR - Failed to import: /home/airflow/dags/Lead_scoring_inference_pipeline/lead_scoring_inference_pipeline.py
Traceback (most recent call last):
  File "/opt/conda/lib/python3.8/site-packages/airflow/models/dagbag.py", line 318, in parse
    loader.exec_module(new_module)
  File "<frozen importlib._bootstrap_external>", line 843, in exec_module
  File "<frozen importlib._bootstrap>", line 219, in _call_with_frames_removed
  File "/home/airflow/dags/Lead_scoring_inference_pipeline/lead_scoring_inference_pipeline.py", line 36, in <module>
    utils = module_from_file("utils", "/airflow/dags/Lead_scoring_inference_pipeline/utils.py")
  File "/home/airflow/dags/Lead_scoring_inference_pipeline/lead_scoring_inference_pipeline.py", line 33, in module_from_file
    spec.loader.exec_module(module)
  File "<frozen importlib._bootstrap_external>", line 839, in exec_module
  File "<frozen importlib._bootstrap_external>", line 975, in get_code
  File "<frozen importlib._bootstrap_external>", line 1032, in get_data
FileNotFoundError: [Errno 2] No such file or directory: '/airflow/dags/Lead_scoring_inference_pipeline/utils.py'
[2024-12-04 12:08:33,171] {processor.py:653} WARNING - No viable dags retrieved from /home/airflow/dags/Lead_scoring_inference_pipeline/lead_scoring_inference_pipeline.py
[2024-12-04 12:08:33,196] {processor.py:161} INFO - Processing /home/airflow/dags/Lead_scoring_inference_pipeline/lead_scoring_inference_pipeline.py took 0.039 seconds
[2024-12-04 12:09:09,501] {processor.py:153} INFO - Started process (PID=8634) to work on /home/airflow/dags/Lead_scoring_inference_pipeline/lead_scoring_inference_pipeline.py
[2024-12-04 12:09:09,502] {processor.py:641} INFO - Processing file /home/airflow/dags/Lead_scoring_inference_pipeline/lead_scoring_inference_pipeline.py for tasks to queue
[2024-12-04 12:09:09,503] {logging_mixin.py:115} INFO - [2024-12-04 12:09:09,503] {dagbag.py:508} INFO - Filling up the DagBag from /home/airflow/dags/Lead_scoring_inference_pipeline/lead_scoring_inference_pipeline.py
[2024-12-04 12:09:09,511] {logging_mixin.py:115} INFO - [2024-12-04 12:09:09,510] {dagbag.py:321} ERROR - Failed to import: /home/airflow/dags/Lead_scoring_inference_pipeline/lead_scoring_inference_pipeline.py
Traceback (most recent call last):
  File "/opt/conda/lib/python3.8/site-packages/airflow/models/dagbag.py", line 318, in parse
    loader.exec_module(new_module)
  File "<frozen importlib._bootstrap_external>", line 843, in exec_module
  File "<frozen importlib._bootstrap>", line 219, in _call_with_frames_removed
  File "/home/airflow/dags/Lead_scoring_inference_pipeline/lead_scoring_inference_pipeline.py", line 36, in <module>
    utils = module_from_file("utils", "/airflow/dags/Lead_scoring_inference_pipeline/utils.py")
  File "/home/airflow/dags/Lead_scoring_inference_pipeline/lead_scoring_inference_pipeline.py", line 33, in module_from_file
    spec.loader.exec_module(module)
  File "<frozen importlib._bootstrap_external>", line 839, in exec_module
  File "<frozen importlib._bootstrap_external>", line 975, in get_code
  File "<frozen importlib._bootstrap_external>", line 1032, in get_data
FileNotFoundError: [Errno 2] No such file or directory: '/airflow/dags/Lead_scoring_inference_pipeline/utils.py'
[2024-12-04 12:09:09,511] {processor.py:653} WARNING - No viable dags retrieved from /home/airflow/dags/Lead_scoring_inference_pipeline/lead_scoring_inference_pipeline.py
[2024-12-04 12:09:09,537] {processor.py:161} INFO - Processing /home/airflow/dags/Lead_scoring_inference_pipeline/lead_scoring_inference_pipeline.py took 0.039 seconds
[2024-12-04 12:09:46,270] {processor.py:153} INFO - Started process (PID=8684) to work on /home/airflow/dags/Lead_scoring_inference_pipeline/lead_scoring_inference_pipeline.py
[2024-12-04 12:09:46,271] {processor.py:641} INFO - Processing file /home/airflow/dags/Lead_scoring_inference_pipeline/lead_scoring_inference_pipeline.py for tasks to queue
[2024-12-04 12:09:46,272] {logging_mixin.py:115} INFO - [2024-12-04 12:09:46,272] {dagbag.py:508} INFO - Filling up the DagBag from /home/airflow/dags/Lead_scoring_inference_pipeline/lead_scoring_inference_pipeline.py
[2024-12-04 12:09:46,280] {logging_mixin.py:115} INFO - [2024-12-04 12:09:46,279] {dagbag.py:321} ERROR - Failed to import: /home/airflow/dags/Lead_scoring_inference_pipeline/lead_scoring_inference_pipeline.py
Traceback (most recent call last):
  File "/opt/conda/lib/python3.8/site-packages/airflow/models/dagbag.py", line 318, in parse
    loader.exec_module(new_module)
  File "<frozen importlib._bootstrap_external>", line 843, in exec_module
  File "<frozen importlib._bootstrap>", line 219, in _call_with_frames_removed
  File "/home/airflow/dags/Lead_scoring_inference_pipeline/lead_scoring_inference_pipeline.py", line 36, in <module>
    utils = module_from_file("utils", "/airflow/dags/Lead_scoring_inference_pipeline/utils.py")
  File "/home/airflow/dags/Lead_scoring_inference_pipeline/lead_scoring_inference_pipeline.py", line 33, in module_from_file
    spec.loader.exec_module(module)
  File "<frozen importlib._bootstrap_external>", line 839, in exec_module
  File "<frozen importlib._bootstrap_external>", line 975, in get_code
  File "<frozen importlib._bootstrap_external>", line 1032, in get_data
FileNotFoundError: [Errno 2] No such file or directory: '/airflow/dags/Lead_scoring_inference_pipeline/utils.py'
[2024-12-04 12:09:46,280] {processor.py:653} WARNING - No viable dags retrieved from /home/airflow/dags/Lead_scoring_inference_pipeline/lead_scoring_inference_pipeline.py
[2024-12-04 12:09:46,307] {processor.py:161} INFO - Processing /home/airflow/dags/Lead_scoring_inference_pipeline/lead_scoring_inference_pipeline.py took 0.041 seconds
[2024-12-04 12:10:26,669] {processor.py:153} INFO - Started process (PID=8746) to work on /home/airflow/dags/Lead_scoring_inference_pipeline/lead_scoring_inference_pipeline.py
[2024-12-04 12:10:26,670] {processor.py:641} INFO - Processing file /home/airflow/dags/Lead_scoring_inference_pipeline/lead_scoring_inference_pipeline.py for tasks to queue
[2024-12-04 12:10:26,671] {logging_mixin.py:115} INFO - [2024-12-04 12:10:26,671] {dagbag.py:508} INFO - Filling up the DagBag from /home/airflow/dags/Lead_scoring_inference_pipeline/lead_scoring_inference_pipeline.py
[2024-12-04 12:10:26,678] {logging_mixin.py:115} INFO - [2024-12-04 12:10:26,677] {dagbag.py:321} ERROR - Failed to import: /home/airflow/dags/Lead_scoring_inference_pipeline/lead_scoring_inference_pipeline.py
Traceback (most recent call last):
  File "/opt/conda/lib/python3.8/site-packages/airflow/models/dagbag.py", line 318, in parse
    loader.exec_module(new_module)
  File "<frozen importlib._bootstrap_external>", line 843, in exec_module
  File "<frozen importlib._bootstrap>", line 219, in _call_with_frames_removed
  File "/home/airflow/dags/Lead_scoring_inference_pipeline/lead_scoring_inference_pipeline.py", line 36, in <module>
    utils = module_from_file("utils", "/airflow/dags/Lead_scoring_inference_pipeline/utils.py")
  File "/home/airflow/dags/Lead_scoring_inference_pipeline/lead_scoring_inference_pipeline.py", line 33, in module_from_file
    spec.loader.exec_module(module)
  File "<frozen importlib._bootstrap_external>", line 839, in exec_module
  File "<frozen importlib._bootstrap_external>", line 975, in get_code
  File "<frozen importlib._bootstrap_external>", line 1032, in get_data
FileNotFoundError: [Errno 2] No such file or directory: '/airflow/dags/Lead_scoring_inference_pipeline/utils.py'
[2024-12-04 12:10:26,678] {processor.py:653} WARNING - No viable dags retrieved from /home/airflow/dags/Lead_scoring_inference_pipeline/lead_scoring_inference_pipeline.py
[2024-12-04 12:10:26,703] {processor.py:161} INFO - Processing /home/airflow/dags/Lead_scoring_inference_pipeline/lead_scoring_inference_pipeline.py took 0.037 seconds
[2024-12-04 12:11:02,594] {processor.py:153} INFO - Started process (PID=8830) to work on /home/airflow/dags/Lead_scoring_inference_pipeline/lead_scoring_inference_pipeline.py
[2024-12-04 12:11:02,595] {processor.py:641} INFO - Processing file /home/airflow/dags/Lead_scoring_inference_pipeline/lead_scoring_inference_pipeline.py for tasks to queue
[2024-12-04 12:11:02,596] {logging_mixin.py:115} INFO - [2024-12-04 12:11:02,595] {dagbag.py:508} INFO - Filling up the DagBag from /home/airflow/dags/Lead_scoring_inference_pipeline/lead_scoring_inference_pipeline.py
[2024-12-04 12:11:02,603] {logging_mixin.py:115} INFO - [2024-12-04 12:11:02,603] {dagbag.py:321} ERROR - Failed to import: /home/airflow/dags/Lead_scoring_inference_pipeline/lead_scoring_inference_pipeline.py
Traceback (most recent call last):
  File "/opt/conda/lib/python3.8/site-packages/airflow/models/dagbag.py", line 318, in parse
    loader.exec_module(new_module)
  File "<frozen importlib._bootstrap_external>", line 843, in exec_module
  File "<frozen importlib._bootstrap>", line 219, in _call_with_frames_removed
  File "/home/airflow/dags/Lead_scoring_inference_pipeline/lead_scoring_inference_pipeline.py", line 36, in <module>
    utils = module_from_file("utils", "/airflow/dags/Lead_scoring_inference_pipeline/utils.py")
  File "/home/airflow/dags/Lead_scoring_inference_pipeline/lead_scoring_inference_pipeline.py", line 33, in module_from_file
    spec.loader.exec_module(module)
  File "<frozen importlib._bootstrap_external>", line 839, in exec_module
  File "<frozen importlib._bootstrap_external>", line 975, in get_code
  File "<frozen importlib._bootstrap_external>", line 1032, in get_data
FileNotFoundError: [Errno 2] No such file or directory: '/airflow/dags/Lead_scoring_inference_pipeline/utils.py'
[2024-12-04 12:11:02,603] {processor.py:653} WARNING - No viable dags retrieved from /home/airflow/dags/Lead_scoring_inference_pipeline/lead_scoring_inference_pipeline.py
[2024-12-04 12:11:02,643] {processor.py:161} INFO - Processing /home/airflow/dags/Lead_scoring_inference_pipeline/lead_scoring_inference_pipeline.py took 0.053 seconds
[2024-12-04 12:11:38,258] {processor.py:153} INFO - Started process (PID=8921) to work on /home/airflow/dags/Lead_scoring_inference_pipeline/lead_scoring_inference_pipeline.py
[2024-12-04 12:11:38,259] {processor.py:641} INFO - Processing file /home/airflow/dags/Lead_scoring_inference_pipeline/lead_scoring_inference_pipeline.py for tasks to queue
[2024-12-04 12:11:38,259] {logging_mixin.py:115} INFO - [2024-12-04 12:11:38,259] {dagbag.py:508} INFO - Filling up the DagBag from /home/airflow/dags/Lead_scoring_inference_pipeline/lead_scoring_inference_pipeline.py
[2024-12-04 12:11:38,267] {logging_mixin.py:115} INFO - [2024-12-04 12:11:38,266] {dagbag.py:321} ERROR - Failed to import: /home/airflow/dags/Lead_scoring_inference_pipeline/lead_scoring_inference_pipeline.py
Traceback (most recent call last):
  File "/opt/conda/lib/python3.8/site-packages/airflow/models/dagbag.py", line 318, in parse
    loader.exec_module(new_module)
  File "<frozen importlib._bootstrap_external>", line 843, in exec_module
  File "<frozen importlib._bootstrap>", line 219, in _call_with_frames_removed
  File "/home/airflow/dags/Lead_scoring_inference_pipeline/lead_scoring_inference_pipeline.py", line 36, in <module>
    utils = module_from_file("utils", "/airflow/dags/Lead_scoring_inference_pipeline/utils.py")
  File "/home/airflow/dags/Lead_scoring_inference_pipeline/lead_scoring_inference_pipeline.py", line 33, in module_from_file
    spec.loader.exec_module(module)
  File "<frozen importlib._bootstrap_external>", line 839, in exec_module
  File "<frozen importlib._bootstrap_external>", line 975, in get_code
  File "<frozen importlib._bootstrap_external>", line 1032, in get_data
FileNotFoundError: [Errno 2] No such file or directory: '/airflow/dags/Lead_scoring_inference_pipeline/utils.py'
[2024-12-04 12:11:38,267] {processor.py:653} WARNING - No viable dags retrieved from /home/airflow/dags/Lead_scoring_inference_pipeline/lead_scoring_inference_pipeline.py
[2024-12-04 12:11:38,297] {processor.py:161} INFO - Processing /home/airflow/dags/Lead_scoring_inference_pipeline/lead_scoring_inference_pipeline.py took 0.042 seconds
[2024-12-04 12:12:13,397] {processor.py:153} INFO - Started process (PID=9030) to work on /home/airflow/dags/Lead_scoring_inference_pipeline/lead_scoring_inference_pipeline.py
[2024-12-04 12:12:13,399] {processor.py:641} INFO - Processing file /home/airflow/dags/Lead_scoring_inference_pipeline/lead_scoring_inference_pipeline.py for tasks to queue
[2024-12-04 12:12:13,399] {logging_mixin.py:115} INFO - [2024-12-04 12:12:13,399] {dagbag.py:508} INFO - Filling up the DagBag from /home/airflow/dags/Lead_scoring_inference_pipeline/lead_scoring_inference_pipeline.py
[2024-12-04 12:12:13,407] {logging_mixin.py:115} INFO - [2024-12-04 12:12:13,406] {dagbag.py:321} ERROR - Failed to import: /home/airflow/dags/Lead_scoring_inference_pipeline/lead_scoring_inference_pipeline.py
Traceback (most recent call last):
  File "/opt/conda/lib/python3.8/site-packages/airflow/models/dagbag.py", line 318, in parse
    loader.exec_module(new_module)
  File "<frozen importlib._bootstrap_external>", line 843, in exec_module
  File "<frozen importlib._bootstrap>", line 219, in _call_with_frames_removed
  File "/home/airflow/dags/Lead_scoring_inference_pipeline/lead_scoring_inference_pipeline.py", line 36, in <module>
    utils = module_from_file("utils", "/airflow/dags/Lead_scoring_inference_pipeline/utils.py")
  File "/home/airflow/dags/Lead_scoring_inference_pipeline/lead_scoring_inference_pipeline.py", line 33, in module_from_file
    spec.loader.exec_module(module)
  File "<frozen importlib._bootstrap_external>", line 839, in exec_module
  File "<frozen importlib._bootstrap_external>", line 975, in get_code
  File "<frozen importlib._bootstrap_external>", line 1032, in get_data
FileNotFoundError: [Errno 2] No such file or directory: '/airflow/dags/Lead_scoring_inference_pipeline/utils.py'
[2024-12-04 12:12:13,407] {processor.py:653} WARNING - No viable dags retrieved from /home/airflow/dags/Lead_scoring_inference_pipeline/lead_scoring_inference_pipeline.py
[2024-12-04 12:12:13,432] {processor.py:161} INFO - Processing /home/airflow/dags/Lead_scoring_inference_pipeline/lead_scoring_inference_pipeline.py took 0.038 seconds
[2024-12-04 12:12:44,513] {processor.py:153} INFO - Started process (PID=9120) to work on /home/airflow/dags/Lead_scoring_inference_pipeline/lead_scoring_inference_pipeline.py
[2024-12-04 12:12:44,514] {processor.py:641} INFO - Processing file /home/airflow/dags/Lead_scoring_inference_pipeline/lead_scoring_inference_pipeline.py for tasks to queue
[2024-12-04 12:12:44,514] {logging_mixin.py:115} INFO - [2024-12-04 12:12:44,514] {dagbag.py:508} INFO - Filling up the DagBag from /home/airflow/dags/Lead_scoring_inference_pipeline/lead_scoring_inference_pipeline.py
[2024-12-04 12:12:44,522] {logging_mixin.py:115} INFO - [2024-12-04 12:12:44,521] {dagbag.py:321} ERROR - Failed to import: /home/airflow/dags/Lead_scoring_inference_pipeline/lead_scoring_inference_pipeline.py
Traceback (most recent call last):
  File "/opt/conda/lib/python3.8/site-packages/airflow/models/dagbag.py", line 318, in parse
    loader.exec_module(new_module)
  File "<frozen importlib._bootstrap_external>", line 843, in exec_module
  File "<frozen importlib._bootstrap>", line 219, in _call_with_frames_removed
  File "/home/airflow/dags/Lead_scoring_inference_pipeline/lead_scoring_inference_pipeline.py", line 36, in <module>
    utils = module_from_file("utils", "/airflow/dags/Lead_scoring_inference_pipeline/utils.py")
  File "/home/airflow/dags/Lead_scoring_inference_pipeline/lead_scoring_inference_pipeline.py", line 33, in module_from_file
    spec.loader.exec_module(module)
  File "<frozen importlib._bootstrap_external>", line 839, in exec_module
  File "<frozen importlib._bootstrap_external>", line 975, in get_code
  File "<frozen importlib._bootstrap_external>", line 1032, in get_data
FileNotFoundError: [Errno 2] No such file or directory: '/airflow/dags/Lead_scoring_inference_pipeline/utils.py'
[2024-12-04 12:12:44,522] {processor.py:653} WARNING - No viable dags retrieved from /home/airflow/dags/Lead_scoring_inference_pipeline/lead_scoring_inference_pipeline.py
[2024-12-04 12:12:44,547] {processor.py:161} INFO - Processing /home/airflow/dags/Lead_scoring_inference_pipeline/lead_scoring_inference_pipeline.py took 0.037 seconds
[2024-12-04 12:13:18,484] {processor.py:153} INFO - Started process (PID=9222) to work on /home/airflow/dags/Lead_scoring_inference_pipeline/lead_scoring_inference_pipeline.py
[2024-12-04 12:13:18,485] {processor.py:641} INFO - Processing file /home/airflow/dags/Lead_scoring_inference_pipeline/lead_scoring_inference_pipeline.py for tasks to queue
[2024-12-04 12:13:18,485] {logging_mixin.py:115} INFO - [2024-12-04 12:13:18,485] {dagbag.py:508} INFO - Filling up the DagBag from /home/airflow/dags/Lead_scoring_inference_pipeline/lead_scoring_inference_pipeline.py
[2024-12-04 12:13:18,493] {logging_mixin.py:115} INFO - [2024-12-04 12:13:18,492] {dagbag.py:321} ERROR - Failed to import: /home/airflow/dags/Lead_scoring_inference_pipeline/lead_scoring_inference_pipeline.py
Traceback (most recent call last):
  File "/opt/conda/lib/python3.8/site-packages/airflow/models/dagbag.py", line 318, in parse
    loader.exec_module(new_module)
  File "<frozen importlib._bootstrap_external>", line 843, in exec_module
  File "<frozen importlib._bootstrap>", line 219, in _call_with_frames_removed
  File "/home/airflow/dags/Lead_scoring_inference_pipeline/lead_scoring_inference_pipeline.py", line 36, in <module>
    utils = module_from_file("utils", "/airflow/dags/Lead_scoring_inference_pipeline/utils.py")
  File "/home/airflow/dags/Lead_scoring_inference_pipeline/lead_scoring_inference_pipeline.py", line 33, in module_from_file
    spec.loader.exec_module(module)
  File "<frozen importlib._bootstrap_external>", line 839, in exec_module
  File "<frozen importlib._bootstrap_external>", line 975, in get_code
  File "<frozen importlib._bootstrap_external>", line 1032, in get_data
FileNotFoundError: [Errno 2] No such file or directory: '/airflow/dags/Lead_scoring_inference_pipeline/utils.py'
[2024-12-04 12:13:18,493] {processor.py:653} WARNING - No viable dags retrieved from /home/airflow/dags/Lead_scoring_inference_pipeline/lead_scoring_inference_pipeline.py
[2024-12-04 12:13:18,517] {processor.py:161} INFO - Processing /home/airflow/dags/Lead_scoring_inference_pipeline/lead_scoring_inference_pipeline.py took 0.036 seconds
[2024-12-04 12:13:52,261] {processor.py:153} INFO - Started process (PID=9322) to work on /home/airflow/dags/Lead_scoring_inference_pipeline/lead_scoring_inference_pipeline.py
[2024-12-04 12:13:52,262] {processor.py:641} INFO - Processing file /home/airflow/dags/Lead_scoring_inference_pipeline/lead_scoring_inference_pipeline.py for tasks to queue
[2024-12-04 12:13:52,263] {logging_mixin.py:115} INFO - [2024-12-04 12:13:52,263] {dagbag.py:508} INFO - Filling up the DagBag from /home/airflow/dags/Lead_scoring_inference_pipeline/lead_scoring_inference_pipeline.py
[2024-12-04 12:13:52,271] {logging_mixin.py:115} INFO - [2024-12-04 12:13:52,270] {dagbag.py:321} ERROR - Failed to import: /home/airflow/dags/Lead_scoring_inference_pipeline/lead_scoring_inference_pipeline.py
Traceback (most recent call last):
  File "/opt/conda/lib/python3.8/site-packages/airflow/models/dagbag.py", line 318, in parse
    loader.exec_module(new_module)
  File "<frozen importlib._bootstrap_external>", line 843, in exec_module
  File "<frozen importlib._bootstrap>", line 219, in _call_with_frames_removed
  File "/home/airflow/dags/Lead_scoring_inference_pipeline/lead_scoring_inference_pipeline.py", line 36, in <module>
    utils = module_from_file("utils", "/airflow/dags/Lead_scoring_inference_pipeline/utils.py")
  File "/home/airflow/dags/Lead_scoring_inference_pipeline/lead_scoring_inference_pipeline.py", line 33, in module_from_file
    spec.loader.exec_module(module)
  File "<frozen importlib._bootstrap_external>", line 839, in exec_module
  File "<frozen importlib._bootstrap_external>", line 975, in get_code
  File "<frozen importlib._bootstrap_external>", line 1032, in get_data
FileNotFoundError: [Errno 2] No such file or directory: '/airflow/dags/Lead_scoring_inference_pipeline/utils.py'
[2024-12-04 12:13:52,271] {processor.py:653} WARNING - No viable dags retrieved from /home/airflow/dags/Lead_scoring_inference_pipeline/lead_scoring_inference_pipeline.py
[2024-12-04 12:13:52,294] {processor.py:161} INFO - Processing /home/airflow/dags/Lead_scoring_inference_pipeline/lead_scoring_inference_pipeline.py took 0.037 seconds
[2024-12-04 12:14:29,004] {processor.py:153} INFO - Started process (PID=9420) to work on /home/airflow/dags/Lead_scoring_inference_pipeline/lead_scoring_inference_pipeline.py
[2024-12-04 12:14:29,005] {processor.py:641} INFO - Processing file /home/airflow/dags/Lead_scoring_inference_pipeline/lead_scoring_inference_pipeline.py for tasks to queue
[2024-12-04 12:14:29,006] {logging_mixin.py:115} INFO - [2024-12-04 12:14:29,006] {dagbag.py:508} INFO - Filling up the DagBag from /home/airflow/dags/Lead_scoring_inference_pipeline/lead_scoring_inference_pipeline.py
[2024-12-04 12:14:29,013] {logging_mixin.py:115} INFO - [2024-12-04 12:14:29,013] {dagbag.py:321} ERROR - Failed to import: /home/airflow/dags/Lead_scoring_inference_pipeline/lead_scoring_inference_pipeline.py
Traceback (most recent call last):
  File "/opt/conda/lib/python3.8/site-packages/airflow/models/dagbag.py", line 318, in parse
    loader.exec_module(new_module)
  File "<frozen importlib._bootstrap_external>", line 843, in exec_module
  File "<frozen importlib._bootstrap>", line 219, in _call_with_frames_removed
  File "/home/airflow/dags/Lead_scoring_inference_pipeline/lead_scoring_inference_pipeline.py", line 36, in <module>
    utils = module_from_file("utils", "/airflow/dags/Lead_scoring_inference_pipeline/utils.py")
  File "/home/airflow/dags/Lead_scoring_inference_pipeline/lead_scoring_inference_pipeline.py", line 33, in module_from_file
    spec.loader.exec_module(module)
  File "<frozen importlib._bootstrap_external>", line 839, in exec_module
  File "<frozen importlib._bootstrap_external>", line 975, in get_code
  File "<frozen importlib._bootstrap_external>", line 1032, in get_data
FileNotFoundError: [Errno 2] No such file or directory: '/airflow/dags/Lead_scoring_inference_pipeline/utils.py'
[2024-12-04 12:14:29,014] {processor.py:653} WARNING - No viable dags retrieved from /home/airflow/dags/Lead_scoring_inference_pipeline/lead_scoring_inference_pipeline.py
[2024-12-04 12:14:29,037] {processor.py:161} INFO - Processing /home/airflow/dags/Lead_scoring_inference_pipeline/lead_scoring_inference_pipeline.py took 0.037 seconds
[2024-12-04 12:15:05,177] {processor.py:153} INFO - Started process (PID=9503) to work on /home/airflow/dags/Lead_scoring_inference_pipeline/lead_scoring_inference_pipeline.py
[2024-12-04 12:15:05,178] {processor.py:641} INFO - Processing file /home/airflow/dags/Lead_scoring_inference_pipeline/lead_scoring_inference_pipeline.py for tasks to queue
[2024-12-04 12:15:05,178] {logging_mixin.py:115} INFO - [2024-12-04 12:15:05,178] {dagbag.py:508} INFO - Filling up the DagBag from /home/airflow/dags/Lead_scoring_inference_pipeline/lead_scoring_inference_pipeline.py
[2024-12-04 12:15:05,186] {logging_mixin.py:115} INFO - [2024-12-04 12:15:05,185] {dagbag.py:321} ERROR - Failed to import: /home/airflow/dags/Lead_scoring_inference_pipeline/lead_scoring_inference_pipeline.py
Traceback (most recent call last):
  File "/opt/conda/lib/python3.8/site-packages/airflow/models/dagbag.py", line 318, in parse
    loader.exec_module(new_module)
  File "<frozen importlib._bootstrap_external>", line 843, in exec_module
  File "<frozen importlib._bootstrap>", line 219, in _call_with_frames_removed
  File "/home/airflow/dags/Lead_scoring_inference_pipeline/lead_scoring_inference_pipeline.py", line 36, in <module>
    utils = module_from_file("utils", "/airflow/dags/Lead_scoring_inference_pipeline/utils.py")
  File "/home/airflow/dags/Lead_scoring_inference_pipeline/lead_scoring_inference_pipeline.py", line 33, in module_from_file
    spec.loader.exec_module(module)
  File "<frozen importlib._bootstrap_external>", line 839, in exec_module
  File "<frozen importlib._bootstrap_external>", line 975, in get_code
  File "<frozen importlib._bootstrap_external>", line 1032, in get_data
FileNotFoundError: [Errno 2] No such file or directory: '/airflow/dags/Lead_scoring_inference_pipeline/utils.py'
[2024-12-04 12:15:05,186] {processor.py:653} WARNING - No viable dags retrieved from /home/airflow/dags/Lead_scoring_inference_pipeline/lead_scoring_inference_pipeline.py
[2024-12-04 12:15:05,211] {processor.py:161} INFO - Processing /home/airflow/dags/Lead_scoring_inference_pipeline/lead_scoring_inference_pipeline.py took 0.038 seconds
[2024-12-04 12:15:45,141] {processor.py:153} INFO - Started process (PID=9569) to work on /home/airflow/dags/Lead_scoring_inference_pipeline/lead_scoring_inference_pipeline.py
[2024-12-04 12:15:45,142] {processor.py:641} INFO - Processing file /home/airflow/dags/Lead_scoring_inference_pipeline/lead_scoring_inference_pipeline.py for tasks to queue
[2024-12-04 12:15:45,143] {logging_mixin.py:115} INFO - [2024-12-04 12:15:45,142] {dagbag.py:508} INFO - Filling up the DagBag from /home/airflow/dags/Lead_scoring_inference_pipeline/lead_scoring_inference_pipeline.py
[2024-12-04 12:15:45,150] {logging_mixin.py:115} INFO - [2024-12-04 12:15:45,150] {dagbag.py:321} ERROR - Failed to import: /home/airflow/dags/Lead_scoring_inference_pipeline/lead_scoring_inference_pipeline.py
Traceback (most recent call last):
  File "/opt/conda/lib/python3.8/site-packages/airflow/models/dagbag.py", line 318, in parse
    loader.exec_module(new_module)
  File "<frozen importlib._bootstrap_external>", line 843, in exec_module
  File "<frozen importlib._bootstrap>", line 219, in _call_with_frames_removed
  File "/home/airflow/dags/Lead_scoring_inference_pipeline/lead_scoring_inference_pipeline.py", line 36, in <module>
    utils = module_from_file("utils", "/airflow/dags/Lead_scoring_inference_pipeline/utils.py")
  File "/home/airflow/dags/Lead_scoring_inference_pipeline/lead_scoring_inference_pipeline.py", line 33, in module_from_file
    spec.loader.exec_module(module)
  File "<frozen importlib._bootstrap_external>", line 839, in exec_module
  File "<frozen importlib._bootstrap_external>", line 975, in get_code
  File "<frozen importlib._bootstrap_external>", line 1032, in get_data
FileNotFoundError: [Errno 2] No such file or directory: '/airflow/dags/Lead_scoring_inference_pipeline/utils.py'
[2024-12-04 12:15:45,150] {processor.py:653} WARNING - No viable dags retrieved from /home/airflow/dags/Lead_scoring_inference_pipeline/lead_scoring_inference_pipeline.py
[2024-12-04 12:15:45,179] {processor.py:161} INFO - Processing /home/airflow/dags/Lead_scoring_inference_pipeline/lead_scoring_inference_pipeline.py took 0.041 seconds
[2024-12-04 12:16:18,669] {processor.py:153} INFO - Started process (PID=9633) to work on /home/airflow/dags/Lead_scoring_inference_pipeline/lead_scoring_inference_pipeline.py
[2024-12-04 12:16:18,670] {processor.py:641} INFO - Processing file /home/airflow/dags/Lead_scoring_inference_pipeline/lead_scoring_inference_pipeline.py for tasks to queue
[2024-12-04 12:16:18,671] {logging_mixin.py:115} INFO - [2024-12-04 12:16:18,671] {dagbag.py:508} INFO - Filling up the DagBag from /home/airflow/dags/Lead_scoring_inference_pipeline/lead_scoring_inference_pipeline.py
[2024-12-04 12:16:18,679] {logging_mixin.py:115} INFO - [2024-12-04 12:16:18,678] {dagbag.py:321} ERROR - Failed to import: /home/airflow/dags/Lead_scoring_inference_pipeline/lead_scoring_inference_pipeline.py
Traceback (most recent call last):
  File "/opt/conda/lib/python3.8/site-packages/airflow/models/dagbag.py", line 318, in parse
    loader.exec_module(new_module)
  File "<frozen importlib._bootstrap_external>", line 843, in exec_module
  File "<frozen importlib._bootstrap>", line 219, in _call_with_frames_removed
  File "/home/airflow/dags/Lead_scoring_inference_pipeline/lead_scoring_inference_pipeline.py", line 36, in <module>
    utils = module_from_file("utils", "/airflow/dags/Lead_scoring_inference_pipeline/utils.py")
  File "/home/airflow/dags/Lead_scoring_inference_pipeline/lead_scoring_inference_pipeline.py", line 33, in module_from_file
    spec.loader.exec_module(module)
  File "<frozen importlib._bootstrap_external>", line 839, in exec_module
  File "<frozen importlib._bootstrap_external>", line 975, in get_code
  File "<frozen importlib._bootstrap_external>", line 1032, in get_data
FileNotFoundError: [Errno 2] No such file or directory: '/airflow/dags/Lead_scoring_inference_pipeline/utils.py'
[2024-12-04 12:16:18,679] {processor.py:653} WARNING - No viable dags retrieved from /home/airflow/dags/Lead_scoring_inference_pipeline/lead_scoring_inference_pipeline.py
[2024-12-04 12:16:18,703] {processor.py:161} INFO - Processing /home/airflow/dags/Lead_scoring_inference_pipeline/lead_scoring_inference_pipeline.py took 0.037 seconds
[2024-12-04 12:16:57,305] {processor.py:153} INFO - Started process (PID=9701) to work on /home/airflow/dags/Lead_scoring_inference_pipeline/lead_scoring_inference_pipeline.py
[2024-12-04 12:16:57,306] {processor.py:641} INFO - Processing file /home/airflow/dags/Lead_scoring_inference_pipeline/lead_scoring_inference_pipeline.py for tasks to queue
[2024-12-04 12:16:57,307] {logging_mixin.py:115} INFO - [2024-12-04 12:16:57,307] {dagbag.py:508} INFO - Filling up the DagBag from /home/airflow/dags/Lead_scoring_inference_pipeline/lead_scoring_inference_pipeline.py
[2024-12-04 12:16:57,315] {logging_mixin.py:115} INFO - [2024-12-04 12:16:57,314] {dagbag.py:321} ERROR - Failed to import: /home/airflow/dags/Lead_scoring_inference_pipeline/lead_scoring_inference_pipeline.py
Traceback (most recent call last):
  File "/opt/conda/lib/python3.8/site-packages/airflow/models/dagbag.py", line 318, in parse
    loader.exec_module(new_module)
  File "<frozen importlib._bootstrap_external>", line 843, in exec_module
  File "<frozen importlib._bootstrap>", line 219, in _call_with_frames_removed
  File "/home/airflow/dags/Lead_scoring_inference_pipeline/lead_scoring_inference_pipeline.py", line 36, in <module>
    utils = module_from_file("utils", "/airflow/dags/Lead_scoring_inference_pipeline/utils.py")
  File "/home/airflow/dags/Lead_scoring_inference_pipeline/lead_scoring_inference_pipeline.py", line 33, in module_from_file
    spec.loader.exec_module(module)
  File "<frozen importlib._bootstrap_external>", line 839, in exec_module
  File "<frozen importlib._bootstrap_external>", line 975, in get_code
  File "<frozen importlib._bootstrap_external>", line 1032, in get_data
FileNotFoundError: [Errno 2] No such file or directory: '/airflow/dags/Lead_scoring_inference_pipeline/utils.py'
[2024-12-04 12:16:57,315] {processor.py:653} WARNING - No viable dags retrieved from /home/airflow/dags/Lead_scoring_inference_pipeline/lead_scoring_inference_pipeline.py
[2024-12-04 12:16:57,339] {processor.py:161} INFO - Processing /home/airflow/dags/Lead_scoring_inference_pipeline/lead_scoring_inference_pipeline.py took 0.037 seconds
[2024-12-04 12:17:38,761] {processor.py:153} INFO - Started process (PID=9772) to work on /home/airflow/dags/Lead_scoring_inference_pipeline/lead_scoring_inference_pipeline.py
[2024-12-04 12:17:38,762] {processor.py:641} INFO - Processing file /home/airflow/dags/Lead_scoring_inference_pipeline/lead_scoring_inference_pipeline.py for tasks to queue
[2024-12-04 12:17:38,763] {logging_mixin.py:115} INFO - [2024-12-04 12:17:38,763] {dagbag.py:508} INFO - Filling up the DagBag from /home/airflow/dags/Lead_scoring_inference_pipeline/lead_scoring_inference_pipeline.py
[2024-12-04 12:17:38,770] {logging_mixin.py:115} INFO - [2024-12-04 12:17:38,770] {dagbag.py:321} ERROR - Failed to import: /home/airflow/dags/Lead_scoring_inference_pipeline/lead_scoring_inference_pipeline.py
Traceback (most recent call last):
  File "/opt/conda/lib/python3.8/site-packages/airflow/models/dagbag.py", line 318, in parse
    loader.exec_module(new_module)
  File "<frozen importlib._bootstrap_external>", line 843, in exec_module
  File "<frozen importlib._bootstrap>", line 219, in _call_with_frames_removed
  File "/home/airflow/dags/Lead_scoring_inference_pipeline/lead_scoring_inference_pipeline.py", line 36, in <module>
    utils = module_from_file("utils", "/airflow/dags/Lead_scoring_inference_pipeline/utils.py")
  File "/home/airflow/dags/Lead_scoring_inference_pipeline/lead_scoring_inference_pipeline.py", line 33, in module_from_file
    spec.loader.exec_module(module)
  File "<frozen importlib._bootstrap_external>", line 839, in exec_module
  File "<frozen importlib._bootstrap_external>", line 975, in get_code
  File "<frozen importlib._bootstrap_external>", line 1032, in get_data
FileNotFoundError: [Errno 2] No such file or directory: '/airflow/dags/Lead_scoring_inference_pipeline/utils.py'
[2024-12-04 12:17:38,771] {processor.py:653} WARNING - No viable dags retrieved from /home/airflow/dags/Lead_scoring_inference_pipeline/lead_scoring_inference_pipeline.py
[2024-12-04 12:17:38,796] {processor.py:161} INFO - Processing /home/airflow/dags/Lead_scoring_inference_pipeline/lead_scoring_inference_pipeline.py took 0.038 seconds
[2024-12-04 12:18:18,713] {processor.py:153} INFO - Started process (PID=9833) to work on /home/airflow/dags/Lead_scoring_inference_pipeline/lead_scoring_inference_pipeline.py
[2024-12-04 12:18:18,714] {processor.py:641} INFO - Processing file /home/airflow/dags/Lead_scoring_inference_pipeline/lead_scoring_inference_pipeline.py for tasks to queue
[2024-12-04 12:18:18,715] {logging_mixin.py:115} INFO - [2024-12-04 12:18:18,715] {dagbag.py:508} INFO - Filling up the DagBag from /home/airflow/dags/Lead_scoring_inference_pipeline/lead_scoring_inference_pipeline.py
[2024-12-04 12:18:18,722] {logging_mixin.py:115} INFO - [2024-12-04 12:18:18,721] {dagbag.py:321} ERROR - Failed to import: /home/airflow/dags/Lead_scoring_inference_pipeline/lead_scoring_inference_pipeline.py
Traceback (most recent call last):
  File "/opt/conda/lib/python3.8/site-packages/airflow/models/dagbag.py", line 318, in parse
    loader.exec_module(new_module)
  File "<frozen importlib._bootstrap_external>", line 843, in exec_module
  File "<frozen importlib._bootstrap>", line 219, in _call_with_frames_removed
  File "/home/airflow/dags/Lead_scoring_inference_pipeline/lead_scoring_inference_pipeline.py", line 36, in <module>
    utils = module_from_file("utils", "/airflow/dags/Lead_scoring_inference_pipeline/utils.py")
  File "/home/airflow/dags/Lead_scoring_inference_pipeline/lead_scoring_inference_pipeline.py", line 33, in module_from_file
    spec.loader.exec_module(module)
  File "<frozen importlib._bootstrap_external>", line 839, in exec_module
  File "<frozen importlib._bootstrap_external>", line 975, in get_code
  File "<frozen importlib._bootstrap_external>", line 1032, in get_data
FileNotFoundError: [Errno 2] No such file or directory: '/airflow/dags/Lead_scoring_inference_pipeline/utils.py'
[2024-12-04 12:18:18,722] {processor.py:653} WARNING - No viable dags retrieved from /home/airflow/dags/Lead_scoring_inference_pipeline/lead_scoring_inference_pipeline.py
[2024-12-04 12:18:18,746] {processor.py:161} INFO - Processing /home/airflow/dags/Lead_scoring_inference_pipeline/lead_scoring_inference_pipeline.py took 0.036 seconds
[2024-12-04 12:18:52,532] {processor.py:153} INFO - Started process (PID=9885) to work on /home/airflow/dags/Lead_scoring_inference_pipeline/lead_scoring_inference_pipeline.py
[2024-12-04 12:18:52,533] {processor.py:641} INFO - Processing file /home/airflow/dags/Lead_scoring_inference_pipeline/lead_scoring_inference_pipeline.py for tasks to queue
[2024-12-04 12:18:52,533] {logging_mixin.py:115} INFO - [2024-12-04 12:18:52,533] {dagbag.py:508} INFO - Filling up the DagBag from /home/airflow/dags/Lead_scoring_inference_pipeline/lead_scoring_inference_pipeline.py
[2024-12-04 12:18:52,541] {logging_mixin.py:115} INFO - [2024-12-04 12:18:52,540] {dagbag.py:321} ERROR - Failed to import: /home/airflow/dags/Lead_scoring_inference_pipeline/lead_scoring_inference_pipeline.py
Traceback (most recent call last):
  File "/opt/conda/lib/python3.8/site-packages/airflow/models/dagbag.py", line 318, in parse
    loader.exec_module(new_module)
  File "<frozen importlib._bootstrap_external>", line 843, in exec_module
  File "<frozen importlib._bootstrap>", line 219, in _call_with_frames_removed
  File "/home/airflow/dags/Lead_scoring_inference_pipeline/lead_scoring_inference_pipeline.py", line 36, in <module>
    utils = module_from_file("utils", "/airflow/dags/Lead_scoring_inference_pipeline/utils.py")
  File "/home/airflow/dags/Lead_scoring_inference_pipeline/lead_scoring_inference_pipeline.py", line 33, in module_from_file
    spec.loader.exec_module(module)
  File "<frozen importlib._bootstrap_external>", line 839, in exec_module
  File "<frozen importlib._bootstrap_external>", line 975, in get_code
  File "<frozen importlib._bootstrap_external>", line 1032, in get_data
FileNotFoundError: [Errno 2] No such file or directory: '/airflow/dags/Lead_scoring_inference_pipeline/utils.py'
[2024-12-04 12:18:52,541] {processor.py:653} WARNING - No viable dags retrieved from /home/airflow/dags/Lead_scoring_inference_pipeline/lead_scoring_inference_pipeline.py
[2024-12-04 12:18:52,569] {processor.py:161} INFO - Processing /home/airflow/dags/Lead_scoring_inference_pipeline/lead_scoring_inference_pipeline.py took 0.041 seconds
[2024-12-04 12:19:29,644] {processor.py:153} INFO - Started process (PID=9936) to work on /home/airflow/dags/Lead_scoring_inference_pipeline/lead_scoring_inference_pipeline.py
[2024-12-04 12:19:29,645] {processor.py:641} INFO - Processing file /home/airflow/dags/Lead_scoring_inference_pipeline/lead_scoring_inference_pipeline.py for tasks to queue
[2024-12-04 12:19:29,646] {logging_mixin.py:115} INFO - [2024-12-04 12:19:29,645] {dagbag.py:508} INFO - Filling up the DagBag from /home/airflow/dags/Lead_scoring_inference_pipeline/lead_scoring_inference_pipeline.py
[2024-12-04 12:19:29,653] {logging_mixin.py:115} INFO - [2024-12-04 12:19:29,652] {dagbag.py:321} ERROR - Failed to import: /home/airflow/dags/Lead_scoring_inference_pipeline/lead_scoring_inference_pipeline.py
Traceback (most recent call last):
  File "/opt/conda/lib/python3.8/site-packages/airflow/models/dagbag.py", line 318, in parse
    loader.exec_module(new_module)
  File "<frozen importlib._bootstrap_external>", line 843, in exec_module
  File "<frozen importlib._bootstrap>", line 219, in _call_with_frames_removed
  File "/home/airflow/dags/Lead_scoring_inference_pipeline/lead_scoring_inference_pipeline.py", line 36, in <module>
    utils = module_from_file("utils", "/airflow/dags/Lead_scoring_inference_pipeline/utils.py")
  File "/home/airflow/dags/Lead_scoring_inference_pipeline/lead_scoring_inference_pipeline.py", line 33, in module_from_file
    spec.loader.exec_module(module)
  File "<frozen importlib._bootstrap_external>", line 839, in exec_module
  File "<frozen importlib._bootstrap_external>", line 975, in get_code
  File "<frozen importlib._bootstrap_external>", line 1032, in get_data
FileNotFoundError: [Errno 2] No such file or directory: '/airflow/dags/Lead_scoring_inference_pipeline/utils.py'
[2024-12-04 12:19:29,653] {processor.py:653} WARNING - No viable dags retrieved from /home/airflow/dags/Lead_scoring_inference_pipeline/lead_scoring_inference_pipeline.py
[2024-12-04 12:19:29,677] {processor.py:161} INFO - Processing /home/airflow/dags/Lead_scoring_inference_pipeline/lead_scoring_inference_pipeline.py took 0.037 seconds
[2024-12-04 12:20:07,940] {processor.py:153} INFO - Started process (PID=10027) to work on /home/airflow/dags/Lead_scoring_inference_pipeline/lead_scoring_inference_pipeline.py
[2024-12-04 12:20:07,942] {processor.py:641} INFO - Processing file /home/airflow/dags/Lead_scoring_inference_pipeline/lead_scoring_inference_pipeline.py for tasks to queue
[2024-12-04 12:20:07,942] {logging_mixin.py:115} INFO - [2024-12-04 12:20:07,942] {dagbag.py:508} INFO - Filling up the DagBag from /home/airflow/dags/Lead_scoring_inference_pipeline/lead_scoring_inference_pipeline.py
[2024-12-04 12:20:07,950] {logging_mixin.py:115} INFO - [2024-12-04 12:20:07,949] {dagbag.py:321} ERROR - Failed to import: /home/airflow/dags/Lead_scoring_inference_pipeline/lead_scoring_inference_pipeline.py
Traceback (most recent call last):
  File "/opt/conda/lib/python3.8/site-packages/airflow/models/dagbag.py", line 318, in parse
    loader.exec_module(new_module)
  File "<frozen importlib._bootstrap_external>", line 843, in exec_module
  File "<frozen importlib._bootstrap>", line 219, in _call_with_frames_removed
  File "/home/airflow/dags/Lead_scoring_inference_pipeline/lead_scoring_inference_pipeline.py", line 36, in <module>
    utils = module_from_file("utils", "/airflow/dags/Lead_scoring_inference_pipeline/utils.py")
  File "/home/airflow/dags/Lead_scoring_inference_pipeline/lead_scoring_inference_pipeline.py", line 33, in module_from_file
    spec.loader.exec_module(module)
  File "<frozen importlib._bootstrap_external>", line 839, in exec_module
  File "<frozen importlib._bootstrap_external>", line 975, in get_code
  File "<frozen importlib._bootstrap_external>", line 1032, in get_data
FileNotFoundError: [Errno 2] No such file or directory: '/airflow/dags/Lead_scoring_inference_pipeline/utils.py'
[2024-12-04 12:20:07,950] {processor.py:653} WARNING - No viable dags retrieved from /home/airflow/dags/Lead_scoring_inference_pipeline/lead_scoring_inference_pipeline.py
[2024-12-04 12:20:07,976] {processor.py:161} INFO - Processing /home/airflow/dags/Lead_scoring_inference_pipeline/lead_scoring_inference_pipeline.py took 0.039 seconds
[2024-12-04 12:20:42,751] {processor.py:153} INFO - Started process (PID=10106) to work on /home/airflow/dags/Lead_scoring_inference_pipeline/lead_scoring_inference_pipeline.py
[2024-12-04 12:20:42,752] {processor.py:641} INFO - Processing file /home/airflow/dags/Lead_scoring_inference_pipeline/lead_scoring_inference_pipeline.py for tasks to queue
[2024-12-04 12:20:42,753] {logging_mixin.py:115} INFO - [2024-12-04 12:20:42,753] {dagbag.py:508} INFO - Filling up the DagBag from /home/airflow/dags/Lead_scoring_inference_pipeline/lead_scoring_inference_pipeline.py
[2024-12-04 12:20:42,761] {logging_mixin.py:115} INFO - [2024-12-04 12:20:42,760] {dagbag.py:321} ERROR - Failed to import: /home/airflow/dags/Lead_scoring_inference_pipeline/lead_scoring_inference_pipeline.py
Traceback (most recent call last):
  File "/opt/conda/lib/python3.8/site-packages/airflow/models/dagbag.py", line 318, in parse
    loader.exec_module(new_module)
  File "<frozen importlib._bootstrap_external>", line 843, in exec_module
  File "<frozen importlib._bootstrap>", line 219, in _call_with_frames_removed
  File "/home/airflow/dags/Lead_scoring_inference_pipeline/lead_scoring_inference_pipeline.py", line 36, in <module>
    utils = module_from_file("utils", "/airflow/dags/Lead_scoring_inference_pipeline/utils.py")
  File "/home/airflow/dags/Lead_scoring_inference_pipeline/lead_scoring_inference_pipeline.py", line 33, in module_from_file
    spec.loader.exec_module(module)
  File "<frozen importlib._bootstrap_external>", line 839, in exec_module
  File "<frozen importlib._bootstrap_external>", line 975, in get_code
  File "<frozen importlib._bootstrap_external>", line 1032, in get_data
FileNotFoundError: [Errno 2] No such file or directory: '/airflow/dags/Lead_scoring_inference_pipeline/utils.py'
[2024-12-04 12:20:42,761] {processor.py:653} WARNING - No viable dags retrieved from /home/airflow/dags/Lead_scoring_inference_pipeline/lead_scoring_inference_pipeline.py
[2024-12-04 12:20:42,786] {processor.py:161} INFO - Processing /home/airflow/dags/Lead_scoring_inference_pipeline/lead_scoring_inference_pipeline.py took 0.038 seconds
[2024-12-04 12:21:18,309] {processor.py:153} INFO - Started process (PID=10155) to work on /home/airflow/dags/Lead_scoring_inference_pipeline/lead_scoring_inference_pipeline.py
[2024-12-04 12:21:18,311] {processor.py:641} INFO - Processing file /home/airflow/dags/Lead_scoring_inference_pipeline/lead_scoring_inference_pipeline.py for tasks to queue
[2024-12-04 12:21:18,311] {logging_mixin.py:115} INFO - [2024-12-04 12:21:18,311] {dagbag.py:508} INFO - Filling up the DagBag from /home/airflow/dags/Lead_scoring_inference_pipeline/lead_scoring_inference_pipeline.py
[2024-12-04 12:21:18,320] {logging_mixin.py:115} INFO - [2024-12-04 12:21:18,319] {dagbag.py:321} ERROR - Failed to import: /home/airflow/dags/Lead_scoring_inference_pipeline/lead_scoring_inference_pipeline.py
Traceback (most recent call last):
  File "/opt/conda/lib/python3.8/site-packages/airflow/models/dagbag.py", line 318, in parse
    loader.exec_module(new_module)
  File "<frozen importlib._bootstrap_external>", line 843, in exec_module
  File "<frozen importlib._bootstrap>", line 219, in _call_with_frames_removed
  File "/home/airflow/dags/Lead_scoring_inference_pipeline/lead_scoring_inference_pipeline.py", line 36, in <module>
    utils = module_from_file("utils", "/airflow/dags/Lead_scoring_inference_pipeline/utils.py")
  File "/home/airflow/dags/Lead_scoring_inference_pipeline/lead_scoring_inference_pipeline.py", line 33, in module_from_file
    spec.loader.exec_module(module)
  File "<frozen importlib._bootstrap_external>", line 839, in exec_module
  File "<frozen importlib._bootstrap_external>", line 975, in get_code
  File "<frozen importlib._bootstrap_external>", line 1032, in get_data
FileNotFoundError: [Errno 2] No such file or directory: '/airflow/dags/Lead_scoring_inference_pipeline/utils.py'
[2024-12-04 12:21:18,320] {processor.py:653} WARNING - No viable dags retrieved from /home/airflow/dags/Lead_scoring_inference_pipeline/lead_scoring_inference_pipeline.py
[2024-12-04 12:21:18,348] {processor.py:161} INFO - Processing /home/airflow/dags/Lead_scoring_inference_pipeline/lead_scoring_inference_pipeline.py took 0.042 seconds
[2024-12-04 12:21:55,880] {processor.py:153} INFO - Started process (PID=10208) to work on /home/airflow/dags/Lead_scoring_inference_pipeline/lead_scoring_inference_pipeline.py
[2024-12-04 12:21:55,882] {processor.py:641} INFO - Processing file /home/airflow/dags/Lead_scoring_inference_pipeline/lead_scoring_inference_pipeline.py for tasks to queue
[2024-12-04 12:21:55,882] {logging_mixin.py:115} INFO - [2024-12-04 12:21:55,882] {dagbag.py:508} INFO - Filling up the DagBag from /home/airflow/dags/Lead_scoring_inference_pipeline/lead_scoring_inference_pipeline.py
[2024-12-04 12:21:55,890] {logging_mixin.py:115} INFO - [2024-12-04 12:21:55,889] {dagbag.py:321} ERROR - Failed to import: /home/airflow/dags/Lead_scoring_inference_pipeline/lead_scoring_inference_pipeline.py
Traceback (most recent call last):
  File "/opt/conda/lib/python3.8/site-packages/airflow/models/dagbag.py", line 318, in parse
    loader.exec_module(new_module)
  File "<frozen importlib._bootstrap_external>", line 843, in exec_module
  File "<frozen importlib._bootstrap>", line 219, in _call_with_frames_removed
  File "/home/airflow/dags/Lead_scoring_inference_pipeline/lead_scoring_inference_pipeline.py", line 36, in <module>
    utils = module_from_file("utils", "/airflow/dags/Lead_scoring_inference_pipeline/utils.py")
  File "/home/airflow/dags/Lead_scoring_inference_pipeline/lead_scoring_inference_pipeline.py", line 33, in module_from_file
    spec.loader.exec_module(module)
  File "<frozen importlib._bootstrap_external>", line 839, in exec_module
  File "<frozen importlib._bootstrap_external>", line 975, in get_code
  File "<frozen importlib._bootstrap_external>", line 1032, in get_data
FileNotFoundError: [Errno 2] No such file or directory: '/airflow/dags/Lead_scoring_inference_pipeline/utils.py'
[2024-12-04 12:21:55,890] {processor.py:653} WARNING - No viable dags retrieved from /home/airflow/dags/Lead_scoring_inference_pipeline/lead_scoring_inference_pipeline.py
[2024-12-04 12:21:55,915] {processor.py:161} INFO - Processing /home/airflow/dags/Lead_scoring_inference_pipeline/lead_scoring_inference_pipeline.py took 0.038 seconds
[2024-12-04 12:22:30,808] {processor.py:153} INFO - Started process (PID=10260) to work on /home/airflow/dags/Lead_scoring_inference_pipeline/lead_scoring_inference_pipeline.py
[2024-12-04 12:22:30,810] {processor.py:641} INFO - Processing file /home/airflow/dags/Lead_scoring_inference_pipeline/lead_scoring_inference_pipeline.py for tasks to queue
[2024-12-04 12:22:30,810] {logging_mixin.py:115} INFO - [2024-12-04 12:22:30,810] {dagbag.py:508} INFO - Filling up the DagBag from /home/airflow/dags/Lead_scoring_inference_pipeline/lead_scoring_inference_pipeline.py
[2024-12-04 12:22:30,818] {logging_mixin.py:115} INFO - [2024-12-04 12:22:30,817] {dagbag.py:321} ERROR - Failed to import: /home/airflow/dags/Lead_scoring_inference_pipeline/lead_scoring_inference_pipeline.py
Traceback (most recent call last):
  File "/opt/conda/lib/python3.8/site-packages/airflow/models/dagbag.py", line 318, in parse
    loader.exec_module(new_module)
  File "<frozen importlib._bootstrap_external>", line 843, in exec_module
  File "<frozen importlib._bootstrap>", line 219, in _call_with_frames_removed
  File "/home/airflow/dags/Lead_scoring_inference_pipeline/lead_scoring_inference_pipeline.py", line 36, in <module>
    utils = module_from_file("utils", "/airflow/dags/Lead_scoring_inference_pipeline/utils.py")
  File "/home/airflow/dags/Lead_scoring_inference_pipeline/lead_scoring_inference_pipeline.py", line 33, in module_from_file
    spec.loader.exec_module(module)
  File "<frozen importlib._bootstrap_external>", line 839, in exec_module
  File "<frozen importlib._bootstrap_external>", line 975, in get_code
  File "<frozen importlib._bootstrap_external>", line 1032, in get_data
FileNotFoundError: [Errno 2] No such file or directory: '/airflow/dags/Lead_scoring_inference_pipeline/utils.py'
[2024-12-04 12:22:30,818] {processor.py:653} WARNING - No viable dags retrieved from /home/airflow/dags/Lead_scoring_inference_pipeline/lead_scoring_inference_pipeline.py
[2024-12-04 12:22:30,842] {processor.py:161} INFO - Processing /home/airflow/dags/Lead_scoring_inference_pipeline/lead_scoring_inference_pipeline.py took 0.037 seconds
[2024-12-04 12:23:09,340] {processor.py:153} INFO - Started process (PID=10312) to work on /home/airflow/dags/Lead_scoring_inference_pipeline/lead_scoring_inference_pipeline.py
[2024-12-04 12:23:09,342] {processor.py:641} INFO - Processing file /home/airflow/dags/Lead_scoring_inference_pipeline/lead_scoring_inference_pipeline.py for tasks to queue
[2024-12-04 12:23:09,342] {logging_mixin.py:115} INFO - [2024-12-04 12:23:09,342] {dagbag.py:508} INFO - Filling up the DagBag from /home/airflow/dags/Lead_scoring_inference_pipeline/lead_scoring_inference_pipeline.py
[2024-12-04 12:23:09,349] {logging_mixin.py:115} INFO - [2024-12-04 12:23:09,349] {dagbag.py:321} ERROR - Failed to import: /home/airflow/dags/Lead_scoring_inference_pipeline/lead_scoring_inference_pipeline.py
Traceback (most recent call last):
  File "/opt/conda/lib/python3.8/site-packages/airflow/models/dagbag.py", line 318, in parse
    loader.exec_module(new_module)
  File "<frozen importlib._bootstrap_external>", line 843, in exec_module
  File "<frozen importlib._bootstrap>", line 219, in _call_with_frames_removed
  File "/home/airflow/dags/Lead_scoring_inference_pipeline/lead_scoring_inference_pipeline.py", line 36, in <module>
    utils = module_from_file("utils", "/airflow/dags/Lead_scoring_inference_pipeline/utils.py")
  File "/home/airflow/dags/Lead_scoring_inference_pipeline/lead_scoring_inference_pipeline.py", line 33, in module_from_file
    spec.loader.exec_module(module)
  File "<frozen importlib._bootstrap_external>", line 839, in exec_module
  File "<frozen importlib._bootstrap_external>", line 975, in get_code
  File "<frozen importlib._bootstrap_external>", line 1032, in get_data
FileNotFoundError: [Errno 2] No such file or directory: '/airflow/dags/Lead_scoring_inference_pipeline/utils.py'
[2024-12-04 12:23:09,350] {processor.py:653} WARNING - No viable dags retrieved from /home/airflow/dags/Lead_scoring_inference_pipeline/lead_scoring_inference_pipeline.py
[2024-12-04 12:23:09,375] {processor.py:161} INFO - Processing /home/airflow/dags/Lead_scoring_inference_pipeline/lead_scoring_inference_pipeline.py took 0.038 seconds
[2024-12-04 12:23:47,628] {processor.py:153} INFO - Started process (PID=10365) to work on /home/airflow/dags/Lead_scoring_inference_pipeline/lead_scoring_inference_pipeline.py
[2024-12-04 12:23:47,629] {processor.py:641} INFO - Processing file /home/airflow/dags/Lead_scoring_inference_pipeline/lead_scoring_inference_pipeline.py for tasks to queue
[2024-12-04 12:23:47,630] {logging_mixin.py:115} INFO - [2024-12-04 12:23:47,630] {dagbag.py:508} INFO - Filling up the DagBag from /home/airflow/dags/Lead_scoring_inference_pipeline/lead_scoring_inference_pipeline.py
[2024-12-04 12:23:47,637] {logging_mixin.py:115} INFO - [2024-12-04 12:23:47,637] {dagbag.py:321} ERROR - Failed to import: /home/airflow/dags/Lead_scoring_inference_pipeline/lead_scoring_inference_pipeline.py
Traceback (most recent call last):
  File "/opt/conda/lib/python3.8/site-packages/airflow/models/dagbag.py", line 318, in parse
    loader.exec_module(new_module)
  File "<frozen importlib._bootstrap_external>", line 843, in exec_module
  File "<frozen importlib._bootstrap>", line 219, in _call_with_frames_removed
  File "/home/airflow/dags/Lead_scoring_inference_pipeline/lead_scoring_inference_pipeline.py", line 36, in <module>
    utils = module_from_file("utils", "/airflow/dags/Lead_scoring_inference_pipeline/utils.py")
  File "/home/airflow/dags/Lead_scoring_inference_pipeline/lead_scoring_inference_pipeline.py", line 33, in module_from_file
    spec.loader.exec_module(module)
  File "<frozen importlib._bootstrap_external>", line 839, in exec_module
  File "<frozen importlib._bootstrap_external>", line 975, in get_code
  File "<frozen importlib._bootstrap_external>", line 1032, in get_data
FileNotFoundError: [Errno 2] No such file or directory: '/airflow/dags/Lead_scoring_inference_pipeline/utils.py'
[2024-12-04 12:23:47,638] {processor.py:653} WARNING - No viable dags retrieved from /home/airflow/dags/Lead_scoring_inference_pipeline/lead_scoring_inference_pipeline.py
[2024-12-04 12:23:47,665] {processor.py:161} INFO - Processing /home/airflow/dags/Lead_scoring_inference_pipeline/lead_scoring_inference_pipeline.py took 0.040 seconds
[2024-12-04 12:24:26,229] {processor.py:153} INFO - Started process (PID=10419) to work on /home/airflow/dags/Lead_scoring_inference_pipeline/lead_scoring_inference_pipeline.py
[2024-12-04 12:24:26,230] {processor.py:641} INFO - Processing file /home/airflow/dags/Lead_scoring_inference_pipeline/lead_scoring_inference_pipeline.py for tasks to queue
[2024-12-04 12:24:26,230] {logging_mixin.py:115} INFO - [2024-12-04 12:24:26,230] {dagbag.py:508} INFO - Filling up the DagBag from /home/airflow/dags/Lead_scoring_inference_pipeline/lead_scoring_inference_pipeline.py
[2024-12-04 12:24:26,239] {logging_mixin.py:115} INFO - [2024-12-04 12:24:26,238] {dagbag.py:321} ERROR - Failed to import: /home/airflow/dags/Lead_scoring_inference_pipeline/lead_scoring_inference_pipeline.py
Traceback (most recent call last):
  File "/opt/conda/lib/python3.8/site-packages/airflow/models/dagbag.py", line 318, in parse
    loader.exec_module(new_module)
  File "<frozen importlib._bootstrap_external>", line 843, in exec_module
  File "<frozen importlib._bootstrap>", line 219, in _call_with_frames_removed
  File "/home/airflow/dags/Lead_scoring_inference_pipeline/lead_scoring_inference_pipeline.py", line 36, in <module>
    utils = module_from_file("utils", "/airflow/dags/Lead_scoring_inference_pipeline/utils.py")
  File "/home/airflow/dags/Lead_scoring_inference_pipeline/lead_scoring_inference_pipeline.py", line 33, in module_from_file
    spec.loader.exec_module(module)
  File "<frozen importlib._bootstrap_external>", line 839, in exec_module
  File "<frozen importlib._bootstrap_external>", line 975, in get_code
  File "<frozen importlib._bootstrap_external>", line 1032, in get_data
FileNotFoundError: [Errno 2] No such file or directory: '/airflow/dags/Lead_scoring_inference_pipeline/utils.py'
[2024-12-04 12:24:26,239] {processor.py:653} WARNING - No viable dags retrieved from /home/airflow/dags/Lead_scoring_inference_pipeline/lead_scoring_inference_pipeline.py
[2024-12-04 12:24:26,263] {processor.py:161} INFO - Processing /home/airflow/dags/Lead_scoring_inference_pipeline/lead_scoring_inference_pipeline.py took 0.038 seconds
[2024-12-04 12:25:02,756] {processor.py:153} INFO - Started process (PID=10470) to work on /home/airflow/dags/Lead_scoring_inference_pipeline/lead_scoring_inference_pipeline.py
[2024-12-04 12:25:02,757] {processor.py:641} INFO - Processing file /home/airflow/dags/Lead_scoring_inference_pipeline/lead_scoring_inference_pipeline.py for tasks to queue
[2024-12-04 12:25:02,758] {logging_mixin.py:115} INFO - [2024-12-04 12:25:02,758] {dagbag.py:508} INFO - Filling up the DagBag from /home/airflow/dags/Lead_scoring_inference_pipeline/lead_scoring_inference_pipeline.py
[2024-12-04 12:25:02,765] {logging_mixin.py:115} INFO - [2024-12-04 12:25:02,764] {dagbag.py:321} ERROR - Failed to import: /home/airflow/dags/Lead_scoring_inference_pipeline/lead_scoring_inference_pipeline.py
Traceback (most recent call last):
  File "/opt/conda/lib/python3.8/site-packages/airflow/models/dagbag.py", line 318, in parse
    loader.exec_module(new_module)
  File "<frozen importlib._bootstrap_external>", line 843, in exec_module
  File "<frozen importlib._bootstrap>", line 219, in _call_with_frames_removed
  File "/home/airflow/dags/Lead_scoring_inference_pipeline/lead_scoring_inference_pipeline.py", line 36, in <module>
    utils = module_from_file("utils", "/airflow/dags/Lead_scoring_inference_pipeline/utils.py")
  File "/home/airflow/dags/Lead_scoring_inference_pipeline/lead_scoring_inference_pipeline.py", line 33, in module_from_file
    spec.loader.exec_module(module)
  File "<frozen importlib._bootstrap_external>", line 839, in exec_module
  File "<frozen importlib._bootstrap_external>", line 975, in get_code
  File "<frozen importlib._bootstrap_external>", line 1032, in get_data
FileNotFoundError: [Errno 2] No such file or directory: '/airflow/dags/Lead_scoring_inference_pipeline/utils.py'
[2024-12-04 12:25:02,765] {processor.py:653} WARNING - No viable dags retrieved from /home/airflow/dags/Lead_scoring_inference_pipeline/lead_scoring_inference_pipeline.py
[2024-12-04 12:25:02,792] {processor.py:161} INFO - Processing /home/airflow/dags/Lead_scoring_inference_pipeline/lead_scoring_inference_pipeline.py took 0.039 seconds
[2024-12-04 12:25:40,217] {processor.py:153} INFO - Started process (PID=10525) to work on /home/airflow/dags/Lead_scoring_inference_pipeline/lead_scoring_inference_pipeline.py
[2024-12-04 12:25:40,218] {processor.py:641} INFO - Processing file /home/airflow/dags/Lead_scoring_inference_pipeline/lead_scoring_inference_pipeline.py for tasks to queue
[2024-12-04 12:25:40,219] {logging_mixin.py:115} INFO - [2024-12-04 12:25:40,219] {dagbag.py:508} INFO - Filling up the DagBag from /home/airflow/dags/Lead_scoring_inference_pipeline/lead_scoring_inference_pipeline.py
[2024-12-04 12:25:40,227] {logging_mixin.py:115} INFO - [2024-12-04 12:25:40,226] {dagbag.py:321} ERROR - Failed to import: /home/airflow/dags/Lead_scoring_inference_pipeline/lead_scoring_inference_pipeline.py
Traceback (most recent call last):
  File "/opt/conda/lib/python3.8/site-packages/airflow/models/dagbag.py", line 318, in parse
    loader.exec_module(new_module)
  File "<frozen importlib._bootstrap_external>", line 843, in exec_module
  File "<frozen importlib._bootstrap>", line 219, in _call_with_frames_removed
  File "/home/airflow/dags/Lead_scoring_inference_pipeline/lead_scoring_inference_pipeline.py", line 36, in <module>
    utils = module_from_file("utils", "/airflow/dags/Lead_scoring_inference_pipeline/utils.py")
  File "/home/airflow/dags/Lead_scoring_inference_pipeline/lead_scoring_inference_pipeline.py", line 33, in module_from_file
    spec.loader.exec_module(module)
  File "<frozen importlib._bootstrap_external>", line 839, in exec_module
  File "<frozen importlib._bootstrap_external>", line 975, in get_code
  File "<frozen importlib._bootstrap_external>", line 1032, in get_data
FileNotFoundError: [Errno 2] No such file or directory: '/airflow/dags/Lead_scoring_inference_pipeline/utils.py'
[2024-12-04 12:25:40,227] {processor.py:653} WARNING - No viable dags retrieved from /home/airflow/dags/Lead_scoring_inference_pipeline/lead_scoring_inference_pipeline.py
[2024-12-04 12:25:40,251] {processor.py:161} INFO - Processing /home/airflow/dags/Lead_scoring_inference_pipeline/lead_scoring_inference_pipeline.py took 0.038 seconds
